Workbook
Name FcstMethods: Lookup!$G$2:$G$4
Name OpExSubsets: Lookup!$A$2:$A$10
Name OpExSubsets: Lookup!$A$2:$A$10
Name RowFilter: Lookup!$B$2:$B$3
Name SelectYesNo: Lookup!$D$2:$D$3
Name SelectYesNo: Lookup!$D$2:$D$3
Name TM1REBUILDOPTION: 1
Name TM1RPTDATARNG1: AllocDefintion!$18:$18
Name TM1RPTDATARNG1: FxVar!$20:$20
Name TM1RPTDATARNG1: TgtVar!$17:$29
Name TM1RPTDATARNG2: AllocDetail!$22:$36
Name TM1RPTDATARNG3: Fcst!$91:$103
Name TM1RPTDATARNG3: PL!$16:$28
Name TM1RPTFMTIDCOL: AllocDefintion!$A$1:$A$9
Name TM1RPTFMTIDCOL: AllocDetail!$A$1:$A$8
Name TM1RPTFMTIDCOL: Fcst!$A$1:$A$80
Name TM1RPTFMTIDCOL: FxVar!$A$1:$A$8
Name TM1RPTFMTIDCOL: PL!$A$1:$A$8
Name TM1RPTFMTIDCOL: TgtVar!$A$1:$A$8
Name TM1RPTFMTRNG: AllocDefintion!$D$1:$L$9
Name TM1RPTFMTRNG: AllocDetail!$C$1:$J$8
Name TM1RPTFMTRNG: Fcst!$C$1:$Q$80
Name TM1RPTFMTRNG: FxVar!$C$1:$H$8
Name TM1RPTFMTRNG: PL!$C$1:$H$8
Name TM1RPTFMTRNG: TgtVar!$C$1:$I$8

Sheet TgtVar
A1: [Begin Format Range]
A2: =0 -> 0
A3: =1 -> 1
A4: =2 -> 2 | H4: 50
A5: =3 -> 3
A6: D
A7: N
A8: [End Format Range] | G8: =VLOOKUP($I$13,Lookup!$D$2:$E$3,2,0) -> 0
C9: =_xll.TM1RPTVIEW("region06:Income Statement:1", $G$8, _xll.TM1RPTTITLE("region06:Currency Calc",$D$13), _xll.TM1RPTTITLE("region06:organization",$C$13), _xll.TM1RPTTITLE("region06:Year",$F$13), _xll.TM1RPTTITLE("region06:Month",$H$13),TM1RPTFMTRNG,TM1RPTFMTIDCOL) -> region06:Income Statement:1
C10: P&L Variance to Target
C12: Organization | D12: Currency | F12: Year | H12: Month | I12: Supress Zero
C13: =_xll.SUBNM("region06:organization","Workflow","101","Caption_Default") -> Massachusetts | D13: =_xll.SUBNM("region06:Currency Calc","Default","Local") -> Local | F13: =_xll.SUBNM("region06:Year","Default","Y2","Caption_Default") -> 2021 | H13: =_xll.SUBNM("region06:Month","MY","Year") -> Year | I13: No
D15: PY Actual | E15: Target | F15: =_xll.SUBNM("region06:Version","Current",_xll.DBR("region06:Calendar","Current Version","String"),"Caption_Default") -> Version1 | G15: Variance | H15: Variance% | I15: Explanation
D16: Prior Year Actual | E16: Target | F16: =_xll.SUBNM("region06:Version","Current",_xll.DBR("region06:Calendar","Current Version","String"),"Caption_Default") -> Version1 | G16: Variance | H16: Variance% | I16: Explanation
A17: =IF(_xll.TM1RPTELISCONSOLIDATED($C$17,$C17),IF(_xll.TM1RPTELLEV($C$17,$C17)<=3,_xll.TM1RPTELLEV($C$17,$C17),"D"),"N") -> N | C17: =_xll.TM1RPTROW($C$9,"region06:Account","Summary",,"Caption_Default",1) -> 4999 Gross Revenue | D17: =_xll.DBRW($C$9,$D$13,$C$13,$F$13,$H$13,$C17,D$16) -> 10495091 | E17: =_xll.DBRW($C$9,$D$13,$C$13,$F$13,$H$13,$C17,E$16) -> 12817315 | F17: =_xll.DBRW($C$9,$D$13,$C$13,$F$13,$H$13,$C17,F$16) -> 27654743 | G17: =_xll.DBRW($C$9,$D$13,$C$13,$F$13,$H$13,$C17,G$16) -> -20569721 | H17: =_xll.DBRW($C$9,$D$13,$C$13,$F$13,$H$13,$C17,H$16) -> -74.380446 | I17: =_xll.DBRW($C$9,$D$13,$C$13,$F$13,$H$13,$C17,I$16)
A18: =IF(_xll.TM1RPTELISCONSOLIDATED($C$17,$C18),IF(_xll.TM1RPTELLEV($C$17,$C18)<=3,_xll.TM1RPTELLEV($C$17,$C18),"D"),"N") -> N | C18: 5999 Cost of Sales | D18: =_xll.DBRW($C$9,$D$13,$C$13,$F$13,$H$13,$C18,D$16) -> 8661808.5 | E18: =_xll.DBRW($C$9,$D$13,$C$13,$F$13,$H$13,$C18,E$16) -> 8811382.7 | F18: =_xll.DBRW($C$9,$D$13,$C$13,$F$13,$H$13,$C18,F$16) -> 20932844 | G18: =_xll.DBRW($C$9,$D$13,$C$13,$F$13,$H$13,$C18,G$16) -> 15012087 | H18: =_xll.DBRW($C$9,$D$13,$C$13,$F$13,$H$13,$C18,H$16) -> 71.715469 | I18: =_xll.DBRW($C$9,$D$13,$C$13,$F$13,$H$13,$C18,I$16)
A19: =IF(_xll.TM1RPTELISCONSOLIDATED($C$17,$C19),IF(_xll.TM1RPTELLEV($C$17,$C19)<=3,_xll.TM1RPTELLEV($C$17,$C19),"D"),"N") -> 2 | C19: Gross Margin | D19: =_xll.DBRW($C$9,$D$13,$C$13,$F$13,$H$13,$C19,D$16) -> 1833282.1 | E19: =_xll.DBRW($C$9,$D$13,$C$13,$F$13,$H$13,$C19,E$16) -> 4005932.4 | F19: =_xll.DBRW($C$9,$D$13,$C$13,$F$13,$H$13,$C19,F$16) -> 6721898.8 | G19: =_xll.DBRW($C$9,$D$13,$C$13,$F$13,$H$13,$C19,G$16) -> -5557633.6 | H19: =_xll.DBRW($C$9,$D$13,$C$13,$F$13,$H$13,$C19,H$16) -> -82.67952 | I19: =_xll.DBRW($C$9,$D$13,$C$13,$F$13,$H$13,$C19,I$16)
A20: =IF(_xll.TM1RPTELISCONSOLIDATED($C$17,$C20),IF(_xll.TM1RPTELLEV($C$17,$C20)<=3,_xll.TM1RPTELLEV($C$17,$C20),"D"),"N") -> 3 | C20: 6099 PAYROLL | D20: =_xll.DBRW($C$9,$D$13,$C$13,$F$13,$H$13,$C20,D$16) -> 710411.92 | E20: =_xll.DBRW($C$9,$D$13,$C$13,$F$13,$H$13,$C20,E$16) -> 710411.92 | F20: =_xll.DBRW($C$9,$D$13,$C$13,$F$13,$H$13,$C20,F$16) -> 688412.59 | G20: =_xll.DBRW($C$9,$D$13,$C$13,$F$13,$H$13,$C20,G$16) -> 7694.3622 | H20: =_xll.DBRW($C$9,$D$13,$C$13,$F$13,$H$13,$C20,H$16) -> 1.1176963 | I20: =_xll.DBRW($C$9,$D$13,$C$13,$F$13,$H$13,$C20,I$16)
A21: =IF(_xll.TM1RPTELISCONSOLIDATED($C$17,$C21),IF(_xll.TM1RPTELLEV($C$17,$C21)<=3,_xll.TM1RPTELLEV($C$17,$C21),"D"),"N") -> 3 | C21: 6199 OFFICE EXPENSE | D21: =_xll.DBRW($C$9,$D$13,$C$13,$F$13,$H$13,$C21,D$16) -> 67120.543 | E21: =_xll.DBRW($C$9,$D$13,$C$13,$F$13,$H$13,$C21,E$16) -> 67120.543 | F21: =_xll.DBRW($C$9,$D$13,$C$13,$F$13,$H$13,$C21,F$16) -> 79201.76 | G21: =_xll.DBRW($C$9,$D$13,$C$13,$F$13,$H$13,$C21,G$16) -> 13297.76 | H21: =_xll.DBRW($C$9,$D$13,$C$13,$F$13,$H$13,$C21,H$16) -> 16.789728 | I21: =_xll.DBRW($C$9,$D$13,$C$13,$F$13,$H$13,$C21,I$16)
A22: =IF(_xll.TM1RPTELISCONSOLIDATED($C$17,$C22),IF(_xll.TM1RPTELLEV($C$17,$C22)<=3,_xll.TM1RPTELLEV($C$17,$C22),"D"),"N") -> 3 | C22: 6299 TRAVEL | D22: =_xll.DBRW($C$9,$D$13,$C$13,$F$13,$H$13,$C22,D$16) -> 45415.518 | E22: =_xll.DBRW($C$9,$D$13,$C$13,$F$13,$H$13,$C22,E$16) -> 45415.518 | F22: =_xll.DBRW($C$9,$D$13,$C$13,$F$13,$H$13,$C22,F$16) -> 45228 | G22: =_xll.DBRW($C$9,$D$13,$C$13,$F$13,$H$13,$C22,G$16) -> 2280 | H22: =_xll.DBRW($C$9,$D$13,$C$13,$F$13,$H$13,$C22,H$16) -> 5.041125 | I22: =_xll.DBRW($C$9,$D$13,$C$13,$F$13,$H$13,$C22,I$16)
A23: =IF(_xll.TM1RPTELISCONSOLIDATED($C$17,$C23),IF(_xll.TM1RPTELLEV($C$17,$C23)<=3,_xll.TM1RPTELLEV($C$17,$C23),"D"),"N") -> 3 | C23: 6399 OCCUPANCY | D23: =_xll.DBRW($C$9,$D$13,$C$13,$F$13,$H$13,$C23,D$16) -> 536653.7 | E23: =_xll.DBRW($C$9,$D$13,$C$13,$F$13,$H$13,$C23,E$16) -> 536653.7 | F23: =_xll.DBRW($C$9,$D$13,$C$13,$F$13,$H$13,$C23,F$16) -> 330000 | G23: =_xll.DBRW($C$9,$D$13,$C$13,$F$13,$H$13,$C23,G$16) -> -175797 | H23: =_xll.DBRW($C$9,$D$13,$C$13,$F$13,$H$13,$C23,H$16) -> -53.271818 | I23: =_xll.DBRW($C$9,$D$13,$C$13,$F$13,$H$13,$C23,I$16)
A24: =IF(_xll.TM1RPTELISCONSOLIDATED($C$17,$C24),IF(_xll.TM1RPTELLEV($C$17,$C24)<=3,_xll.TM1RPTELLEV($C$17,$C24),"D"),"N") -> 3 | C24: 6499 MARKETING | D24: =_xll.DBRW($C$9,$D$13,$C$13,$F$13,$H$13,$C24,D$16) -> 99851.304 | E24: =_xll.DBRW($C$9,$D$13,$C$13,$F$13,$H$13,$C24,E$16) -> 99851.304 | F24: =_xll.DBRW($C$9,$D$13,$C$13,$F$13,$H$13,$C24,F$16) -> 681310.8 | G24: =_xll.DBRW($C$9,$D$13,$C$13,$F$13,$H$13,$C24,G$16) -> 581086.8 | H24: =_xll.DBRW($C$9,$D$13,$C$13,$F$13,$H$13,$C24,H$16) -> 85.289533 | I24: =_xll.DBRW($C$9,$D$13,$C$13,$F$13,$H$13,$C24,I$16)
A25: =IF(_xll.TM1RPTELISCONSOLIDATED($C$17,$C25),IF(_xll.TM1RPTELLEV($C$17,$C25)<=3,_xll.TM1RPTELLEV($C$17,$C25),"D"),"N") -> 3 | C25: 6599 DEPRECIATION | D25: =_xll.DBRW($C$9,$D$13,$C$13,$F$13,$H$13,$C25,D$16) -> 134270.06 | E25: =_xll.DBRW($C$9,$D$13,$C$13,$F$13,$H$13,$C25,E$16) -> 134270.06 | F25: =_xll.DBRW($C$9,$D$13,$C$13,$F$13,$H$13,$C25,F$16) -> 170583.33 | G25: =_xll.DBRW($C$9,$D$13,$C$13,$F$13,$H$13,$C25,G$16) -> 26583.333 | H25: =_xll.DBRW($C$9,$D$13,$C$13,$F$13,$H$13,$C25,H$16) -> 15.583781 | I25: =_xll.DBRW($C$9,$D$13,$C$13,$F$13,$H$13,$C25,I$16)
A26: =IF(_xll.TM1RPTELISCONSOLIDATED($C$17,$C26),IF(_xll.TM1RPTELLEV($C$17,$C26)<=3,_xll.TM1RPTELLEV($C$17,$C26),"D"),"N") -> 2 | C26: Total Operating Expense | D26: =_xll.DBRW($C$9,$D$13,$C$13,$F$13,$H$13,$C26,D$16) -> 1593723 | E26: =_xll.DBRW($C$9,$D$13,$C$13,$F$13,$H$13,$C26,E$16) -> 1593723 | F26: =_xll.DBRW($C$9,$D$13,$C$13,$F$13,$H$13,$C26,F$16) -> 1994736.5 | G26: =_xll.DBRW($C$9,$D$13,$C$13,$F$13,$H$13,$C26,G$16) -> 455145.26 | H26: =_xll.DBRW($C$9,$D$13,$C$13,$F$13,$H$13,$C26,H$16) -> 22.817312 | I26: =_xll.DBRW($C$9,$D$13,$C$13,$F$13,$H$13,$C26,I$16)
A27: =IF(_xll.TM1RPTELISCONSOLIDATED($C$17,$C27),IF(_xll.TM1RPTELLEV($C$17,$C27)<=3,_xll.TM1RPTELLEV($C$17,$C27),"D"),"N") -> 1 | C27: Net Profit | D27: =_xll.DBRW($C$9,$D$13,$C$13,$F$13,$H$13,$C27,D$16) -> 239559.04 | E27: =_xll.DBRW($C$9,$D$13,$C$13,$F$13,$H$13,$C27,E$16) -> 2412209.3 | F27: =_xll.DBRW($C$9,$D$13,$C$13,$F$13,$H$13,$C27,F$16) -> 4727162.3 | G27: =_xll.DBRW($C$9,$D$13,$C$13,$F$13,$H$13,$C27,G$16) -> -5102488.4 | H27: =_xll.DBRW($C$9,$D$13,$C$13,$F$13,$H$13,$C27,H$16) -> -107.93978 | I27: =_xll.DBRW($C$9,$D$13,$C$13,$F$13,$H$13,$C27,I$16)
A28: =IF(_xll.TM1RPTELISCONSOLIDATED($C$17,$C28),IF(_xll.TM1RPTELLEV($C$17,$C28)<=3,_xll.TM1RPTELLEV($C$17,$C28),"D"),"N") -> 1 | C28: 6699 ALLOCATIONS | D28: =_xll.DBRW($C$9,$D$13,$C$13,$F$13,$H$13,$C28,D$16) -> 11965.313 | E28: =_xll.DBRW($C$9,$D$13,$C$13,$F$13,$H$13,$C28,E$16) -> 11965.313 | F28: =_xll.DBRW($C$9,$D$13,$C$13,$F$13,$H$13,$C28,F$16) -> 250108.26 | G28: =_xll.DBRW($C$9,$D$13,$C$13,$F$13,$H$13,$C28,G$16) -> 218379.38 | H28: =_xll.DBRW($C$9,$D$13,$C$13,$F$13,$H$13,$C28,H$16) -> 87.313939 | I28: =_xll.DBRW($C$9,$D$13,$C$13,$F$13,$H$13,$C28,I$16)
A29: =IF(_xll.TM1RPTELISCONSOLIDATED($C$17,$C29),IF(_xll.TM1RPTELLEV($C$17,$C29)<=3,_xll.TM1RPTELLEV($C$17,$C29),"D"),"N") -> 0 | C29: Net Profit After Allocations | D29: =_xll.DBRW($C$9,$D$13,$C$13,$F$13,$H$13,$C29,D$16) -> 227593.73 | E29: =_xll.DBRW($C$9,$D$13,$C$13,$F$13,$H$13,$C29,E$16) -> 2400244 | F29: =_xll.DBRW($C$9,$D$13,$C$13,$F$13,$H$13,$C29,F$16) -> 4477054 | G29: =_xll.DBRW($C$9,$D$13,$C$13,$F$13,$H$13,$C29,G$16) -> -4884109 | H29: =_xll.DBRW($C$9,$D$13,$C$13,$F$13,$H$13,$C29,H$16) -> -109.09203 | I29: =_xll.DBRW($C$9,$D$13,$C$13,$F$13,$H$13,$C29,I$16)
C32: Observations:
C33: ="Net Profit for " & C13 & IF(G29>0, "has increased ", "has decreased ") & ROUND(G29,0) & " $ compared to previous year." -> Net Profit for Massachusettshas decreased -4884109 $ compared to previous year.
C34: ="In the mean while, OPEX increased " & ROUND(H26,2) & "%" -> In the mean while, OPEX increased 22.82%

Sheet PL
A1: [Begin Format Range]
A2: =0 -> 0
A3: =1 -> 1
A4: =2 -> 2
A5: =3 -> 3
A6: D
A7: N
A8: [End Format Range] | G8: =VLOOKUP($G$13,Lookup!$D$2:$E$3,2,0) -> 0 | H8: =IF(#REF!<>"","{TM1FILTERBYPATTERN( {TM1SUBSETALL( [Account] )}, """&#REF!&""")}","") -> #REF!
C9: =_xll.TM1RPTVIEW("region06:Income Statement:3", $G$8, _xll.TM1RPTTITLE("region06:Currency Calc",$D$13), _xll.TM1RPTTITLE("region06:organization",$C$13), _xll.TM1RPTTITLE("region06:Year",$E$13), _xll.TM1RPTTITLE("region06:Version",$F$13),TM1RPTFMTRNG,TM1RPTFMTIDCOL) -> region06:Income Statement:3
C10: P&L
C12: Organization | D12: Currency | E12: Year | F12: Version | G12: Supress Zero
C13: =_xll.SUBNM("region06:organization","Workflow","101","Caption_Default") -> Massachusetts | D13: =_xll.SUBNM("region06:Currency Calc","Default","Local") -> Local | E13: =_xll.SUBNM("region06:Year","Default","Y2","Caption_Default") -> 2021 | F13: =_xll.SUBNM("region06:Version","Current",_xll.DBR("region06:Calendar","Current Version","String"),"Caption_Default") -> Version1 | G13: No
D15: Year | E15: Q1 | F15: Q2 | G15: Q3 | H15: Q4
A16: =IF(_xll.TM1RPTELISCONSOLIDATED($C$16,$C16),IF(_xll.TM1RPTELLEV($C$16,$C16)<=3,_xll.TM1RPTELLEV($C$16,$C16),"D"),"N") -> N | C16: =_xll.TM1RPTROW($C$9,"region06:Account","Summary",,"Caption_Default",1) -> 4999 Gross Revenue | D16: =_xll.DBRW($C$9,$D$13,$C$13,$E$13,D$15,$C16,$F$13) -> 27654743 | E16: =_xll.DBRW($C$9,$D$13,$C$13,$E$13,E$15,$C16,$F$13) -> 12209672 | F16: =_xll.DBRW($C$9,$D$13,$C$13,$E$13,F$15,$C16,$F$13) -> 2737365 | G16: =_xll.DBRW($C$9,$D$13,$C$13,$E$13,G$15,$C16,$F$13) -> 9730066.8 | H16: =_xll.DBRW($C$9,$D$13,$C$13,$E$13,H$15,$C16,$F$13) -> 2977639.2
A17: =IF(_xll.TM1RPTELISCONSOLIDATED($C$16,$C17),IF(_xll.TM1RPTELLEV($C$16,$C17)<=3,_xll.TM1RPTELLEV($C$16,$C17),"D"),"N") -> N | C17: 5999 Cost of Sales | D17: =_xll.DBRW($C$9,$D$13,$C$13,$E$13,D$15,$C17,$F$13) -> 20932844 | E17: =_xll.DBRW($C$9,$D$13,$C$13,$E$13,E$15,$C17,$F$13) -> 9302413.9 | F17: =_xll.DBRW($C$9,$D$13,$C$13,$E$13,F$15,$C17,$F$13) -> 2147987.4 | G17: =_xll.DBRW($C$9,$D$13,$C$13,$E$13,G$15,$C17,$F$13) -> 7251005.1 | H17: =_xll.DBRW($C$9,$D$13,$C$13,$E$13,H$15,$C17,$F$13) -> 2231437.5
A18: =IF(_xll.TM1RPTELISCONSOLIDATED($C$16,$C18),IF(_xll.TM1RPTELLEV($C$16,$C18)<=3,_xll.TM1RPTELLEV($C$16,$C18),"D"),"N") -> 2 | C18: Gross Margin | D18: =_xll.DBRW($C$9,$D$13,$C$13,$E$13,D$15,$C18,$F$13) -> 6721898.8 | E18: =_xll.DBRW($C$9,$D$13,$C$13,$E$13,E$15,$C18,$F$13) -> 2907257.7 | F18: =_xll.DBRW($C$9,$D$13,$C$13,$E$13,F$15,$C18,$F$13) -> 589377.65 | G18: =_xll.DBRW($C$9,$D$13,$C$13,$E$13,G$15,$C18,$F$13) -> 2479061.7 | H18: =_xll.DBRW($C$9,$D$13,$C$13,$E$13,H$15,$C18,$F$13) -> 746201.71
A19: =IF(_xll.TM1RPTELISCONSOLIDATED($C$16,$C19),IF(_xll.TM1RPTELLEV($C$16,$C19)<=3,_xll.TM1RPTELLEV($C$16,$C19),"D"),"N") -> 3 | C19: 6099 PAYROLL | D19: =_xll.DBRW($C$9,$D$13,$C$13,$E$13,D$15,$C19,$F$13) -> 688412.59 | E19: =_xll.DBRW($C$9,$D$13,$C$13,$E$13,E$15,$C19,$F$13) -> 176432.15 | F19: =_xll.DBRW($C$9,$D$13,$C$13,$E$13,F$15,$C19,$F$13) -> 187150.53 | G19: =_xll.DBRW($C$9,$D$13,$C$13,$E$13,G$15,$C19,$F$13) -> 175431.98 | H19: =_xll.DBRW($C$9,$D$13,$C$13,$E$13,H$15,$C19,$F$13) -> 149397.93
A20: =IF(_xll.TM1RPTELISCONSOLIDATED($C$16,$C20),IF(_xll.TM1RPTELLEV($C$16,$C20)<=3,_xll.TM1RPTELLEV($C$16,$C20),"D"),"N") -> 3 | C20: 6199 OFFICE EXPENSE | D20: =_xll.DBRW($C$9,$D$13,$C$13,$E$13,D$15,$C20,$F$13) -> 79201.76 | E20: =_xll.DBRW($C$9,$D$13,$C$13,$E$13,E$15,$C20,$F$13) -> 19900.94 | F20: =_xll.DBRW($C$9,$D$13,$C$13,$E$13,F$15,$C20,$F$13) -> 19766.94 | G20: =_xll.DBRW($C$9,$D$13,$C$13,$E$13,G$15,$C20,$F$13) -> 19766.94 | H20: =_xll.DBRW($C$9,$D$13,$C$13,$E$13,H$15,$C20,$F$13) -> 19766.94
A21: =IF(_xll.TM1RPTELISCONSOLIDATED($C$16,$C21),IF(_xll.TM1RPTELLEV($C$16,$C21)<=3,_xll.TM1RPTELLEV($C$16,$C21),"D"),"N") -> 3 | C21: 6299 TRAVEL | D21: =_xll.DBRW($C$9,$D$13,$C$13,$E$13,D$15,$C21,$F$13) -> 45228 | E21: =_xll.DBRW($C$9,$D$13,$C$13,$E$13,E$15,$C21,$F$13) -> 11307 | F21: =_xll.DBRW($C$9,$D$13,$C$13,$E$13,F$15,$C21,$F$13) -> 11307 | G21: =_xll.DBRW($C$9,$D$13,$C$13,$E$13,G$15,$C21,$F$13) -> 11307 | H21: =_xll.DBRW($C$9,$D$13,$C$13,$E$13,H$15,$C21,$F$13) -> 11307
A22: =IF(_xll.TM1RPTELISCONSOLIDATED($C$16,$C22),IF(_xll.TM1RPTELLEV($C$16,$C22)<=3,_xll.TM1RPTELLEV($C$16,$C22),"D"),"N") -> 3 | C22: 6399 OCCUPANCY | D22: =_xll.DBRW($C$9,$D$13,$C$13,$E$13,D$15,$C22,$F$13) -> 330000 | E22: =_xll.DBRW($C$9,$D$13,$C$13,$E$13,E$15,$C22,$F$13) -> 40714.286 | F22: =_xll.DBRW($C$9,$D$13,$C$13,$E$13,F$15,$C22,$F$13) -> 168571.43 | G22: =_xll.DBRW($C$9,$D$13,$C$13,$E$13,G$15,$C22,$F$13) -> 52500 | H22: =_xll.DBRW($C$9,$D$13,$C$13,$E$13,H$15,$C22,$F$13) -> 68214.286
A23: =IF(_xll.TM1RPTELISCONSOLIDATED($C$16,$C23),IF(_xll.TM1RPTELLEV($C$16,$C23)<=3,_xll.TM1RPTELLEV($C$16,$C23),"D"),"N") -> 3 | C23: 6499 MARKETING | D23: =_xll.DBRW($C$9,$D$13,$C$13,$E$13,D$15,$C23,$F$13) -> 681310.8 | E23: =_xll.DBRW($C$9,$D$13,$C$13,$E$13,E$15,$C23,$F$13) -> 599621.8 | F23: =_xll.DBRW($C$9,$D$13,$C$13,$E$13,F$15,$C23,$F$13) -> 28096.069 | G23: =_xll.DBRW($C$9,$D$13,$C$13,$E$13,G$15,$C23,$F$13) -> 26767.101 | H23: =_xll.DBRW($C$9,$D$13,$C$13,$E$13,H$15,$C23,$F$13) -> 26825.829
A24: =IF(_xll.TM1RPTELISCONSOLIDATED($C$16,$C24),IF(_xll.TM1RPTELLEV($C$16,$C24)<=3,_xll.TM1RPTELLEV($C$16,$C24),"D"),"N") -> 3 | C24: 6599 DEPRECIATION | D24: =_xll.DBRW($C$9,$D$13,$C$13,$E$13,D$15,$C24,$F$13) -> 170583.33 | E24: =_xll.DBRW($C$9,$D$13,$C$13,$E$13,E$15,$C24,$F$13) -> 250 | F24: =_xll.DBRW($C$9,$D$13,$C$13,$E$13,F$15,$C24,$F$13) -> 30208.333 | G24: =_xll.DBRW($C$9,$D$13,$C$13,$E$13,G$15,$C24,$F$13) -> 54750 | H24: =_xll.DBRW($C$9,$D$13,$C$13,$E$13,H$15,$C24,$F$13) -> 85375
A25: =IF(_xll.TM1RPTELISCONSOLIDATED($C$16,$C25),IF(_xll.TM1RPTELLEV($C$16,$C25)<=3,_xll.TM1RPTELLEV($C$16,$C25),"D"),"N") -> 2 | C25: Total Operating Expense | D25: =_xll.DBRW($C$9,$D$13,$C$13,$E$13,D$15,$C25,$F$13) -> 1994736.5 | E25: =_xll.DBRW($C$9,$D$13,$C$13,$E$13,E$15,$C25,$F$13) -> 848226.17 | F25: =_xll.DBRW($C$9,$D$13,$C$13,$E$13,F$15,$C25,$F$13) -> 445100.3 | G25: =_xll.DBRW($C$9,$D$13,$C$13,$E$13,G$15,$C25,$F$13) -> 340523.02 | H25: =_xll.DBRW($C$9,$D$13,$C$13,$E$13,H$15,$C25,$F$13) -> 360886.99
A26: =IF(_xll.TM1RPTELISCONSOLIDATED($C$16,$C26),IF(_xll.TM1RPTELLEV($C$16,$C26)<=3,_xll.TM1RPTELLEV($C$16,$C26),"D"),"N") -> 1 | C26: Net Profit | D26: =_xll.DBRW($C$9,$D$13,$C$13,$E$13,D$15,$C26,$F$13) -> 4727162.3 | E26: =_xll.DBRW($C$9,$D$13,$C$13,$E$13,E$15,$C26,$F$13) -> 2059031.5 | F26: =_xll.DBRW($C$9,$D$13,$C$13,$E$13,F$15,$C26,$F$13) -> 144277.35 | G26: =_xll.DBRW($C$9,$D$13,$C$13,$E$13,G$15,$C26,$F$13) -> 2138538.7 | H26: =_xll.DBRW($C$9,$D$13,$C$13,$E$13,H$15,$C26,$F$13) -> 385314.72
A27: =IF(_xll.TM1RPTELISCONSOLIDATED($C$16,$C27),IF(_xll.TM1RPTELLEV($C$16,$C27)<=3,_xll.TM1RPTELLEV($C$16,$C27),"D"),"N") -> 1 | C27: 6699 ALLOCATIONS | D27: =_xll.DBRW($C$9,$D$13,$C$13,$E$13,D$15,$C27,$F$13) -> 250108.26 | E27: =_xll.DBRW($C$9,$D$13,$C$13,$E$13,E$15,$C27,$F$13) -> 46293.191 | F27: =_xll.DBRW($C$9,$D$13,$C$13,$E$13,F$15,$C27,$F$13) -> 55346.231 | G27: =_xll.DBRW($C$9,$D$13,$C$13,$E$13,G$15,$C27,$F$13) -> 71329.769 | H27: =_xll.DBRW($C$9,$D$13,$C$13,$E$13,H$15,$C27,$F$13) -> 77139.07
A28: =IF(_xll.TM1RPTELISCONSOLIDATED($C$16,$C28),IF(_xll.TM1RPTELLEV($C$16,$C28)<=3,_xll.TM1RPTELLEV($C$16,$C28),"D"),"N") -> 0 | C28: Net Profit After Allocations | D28: =_xll.DBRW($C$9,$D$13,$C$13,$E$13,D$15,$C28,$F$13) -> 4477054 | E28: =_xll.DBRW($C$9,$D$13,$C$13,$E$13,E$15,$C28,$F$13) -> 2012738.3 | F28: =_xll.DBRW($C$9,$D$13,$C$13,$E$13,F$15,$C28,$F$13) -> 88931.12 | G28: =_xll.DBRW($C$9,$D$13,$C$13,$E$13,G$15,$C28,$F$13) -> 2067208.9 | H28: =_xll.DBRW($C$9,$D$13,$C$13,$E$13,H$15,$C28,$F$13) -> 308175.65
M62: Q1 | N62: Q2 | O62: Q3 | P62: Q4
L63: 6099 PAYROLL | M63: =_xll.DBRW($C$9,$D$13,$C$13,$E$13,E$15,$L63,$F$13) -> 176432.15 | N63: =_xll.DBRW($C$9,$D$13,$C$13,$E$13,F$15,$L63,$F$13) -> 187150.53 | O63: =_xll.DBRW($C$9,$D$13,$C$13,$E$13,G$15,$L63,$F$13) -> 175431.98 | P63: =_xll.DBRW($C$9,$D$13,$C$13,$E$13,H$15,$L63,$F$13) -> 149397.93
L64: 6199 OFFICE EXPENSE | M64: =_xll.DBRW($C$9,$D$13,$C$13,$E$13,E$15,$L64,$F$13) -> 19900.94 | N64: =_xll.DBRW($C$9,$D$13,$C$13,$E$13,F$15,$L64,$F$13) -> 19766.94 | O64: =_xll.DBRW($C$9,$D$13,$C$13,$E$13,G$15,$L64,$F$13) -> 19766.94 | P64: =_xll.DBRW($C$9,$D$13,$C$13,$E$13,H$15,$L64,$F$13) -> 19766.94
L65: 6299 TRAVEL | M65: =_xll.DBRW($C$9,$D$13,$C$13,$E$13,E$15,$L65,$F$13) -> 11307 | N65: =_xll.DBRW($C$9,$D$13,$C$13,$E$13,F$15,$L65,$F$13) -> 11307 | O65: =_xll.DBRW($C$9,$D$13,$C$13,$E$13,G$15,$L65,$F$13) -> 11307 | P65: =_xll.DBRW($C$9,$D$13,$C$13,$E$13,H$15,$L65,$F$13) -> 11307
L66: 6399 OCCUPANCY | M66: =_xll.DBRW($C$9,$D$13,$C$13,$E$13,E$15,$L66,$F$13) -> 40714.286 | N66: =_xll.DBRW($C$9,$D$13,$C$13,$E$13,F$15,$L66,$F$13) -> 168571.43 | O66: =_xll.DBRW($C$9,$D$13,$C$13,$E$13,G$15,$L66,$F$13) -> 52500 | P66: =_xll.DBRW($C$9,$D$13,$C$13,$E$13,H$15,$L66,$F$13) -> 68214.286
L67: 6499 MARKETING | M67: =_xll.DBRW($C$9,$D$13,$C$13,$E$13,E$15,$L67,$F$13) -> 599621.8 | N67: =_xll.DBRW($C$9,$D$13,$C$13,$E$13,F$15,$L67,$F$13) -> 28096.069 | O67: =_xll.DBRW($C$9,$D$13,$C$13,$E$13,G$15,$L67,$F$13) -> 26767.101 | P67: =_xll.DBRW($C$9,$D$13,$C$13,$E$13,H$15,$L67,$F$13) -> 26825.829
L68: 6599 DEPRECIATION | M68: =_xll.DBRW($C$9,$D$13,$C$13,$E$13,E$15,$L68,$F$13) -> 250 | N68: =_xll.DBRW($C$9,$D$13,$C$13,$E$13,F$15,$L68,$F$13) -> 30208.333 | O68: =_xll.DBRW($C$9,$D$13,$C$13,$E$13,G$15,$L68,$F$13) -> 54750 | P68: =_xll.DBRW($C$9,$D$13,$C$13,$E$13,H$15,$L68,$F$13) -> 85375

Sheet AllocDefintion
A1: [Begin Format Range]
A2: =0 -> 0
A3: =1 -> 1
A4: =2 -> 2
A5: =3 -> 3
A6: D
A7: N
A8: 1_All
A9: [End Format Range]
D10: =_xll.TM1RPTVIEW("region06:Allocation Source Definition:1", 0, _xll.TM1RPTTITLE("region06:Year",$D$14), _xll.TM1RPTTITLE("region06:Version",$F$14),TM1RPTFMTRNG,TM1RPTFMTIDCOL) -> region06:Allocation Source Definition:1
D11: Allocation Definition
D13: Year | F13: Version
D14: =_xll.SUBNM("region06:Year","Default","Y2","Caption_Default") -> 2021 | F14: =_xll.SUBNM("region06:Version","Current",_xll.DBR("region06:Calendar","Current Version","String"),"Caption_Default") -> Version1
F16: Source Entity | G16: Desc | H16: Source Account | I16: Source Amount | J16: Pct to Allocate | K16: Allocation Amount | L16: Allocation Driver
F17: Source Entity | G17: Desc | H17: Source Account | I17: Source Amount | J17: Pct to Allocate | K17: Allocation Amount | L17: Allocation Driver
A18: =IF(D18="All Allocations","1_All",IF(OR(_xll.DBR($D$10,$D18,$D$14,$F$14,"zSource")=PL!$C$13,_xll.DBR($D$10,$D18,$D$14,$F$14,"zSource")=""),1,0)) -> #VALUE! | C18: =IF(MOD(ROW(),2)=1,"G","W") -> W | D18: =_xll.TM1RPTROW($D$10,"region06:Allocation List","L0 Allocations") | E18: =IF(F18="","",IF(A18=1,"→",IF(A18=0,"←",""))) -> #VALUE! | F18: =_xll.DBRW($D$10,$D18,$D$14,$F$14,F$17) -> #VALUE! | G18: =_xll.DBRW($D$10,$D18,$D$14,$F$14,G$17) -> #VALUE! | H18: =_xll.DBRW($D$10,$D18,$D$14,$F$14,H$17) -> #VALUE! | I18: =_xll.DBRW($D$10,$D18,$D$14,$F$14,I$17) -> #VALUE! | J18: =_xll.DBRW($D$10,$D18,$D$14,$F$14,J$17) -> #VALUE! | K18: =_xll.DBRW($D$10,$D18,$D$14,$F$14,K$17) -> #VALUE! | L18: =_xll.DBRW($D$10,$D18,$D$14,$F$14,L$17) -> #VALUE!

Sheet AllocDetail
A1: [Begin Format Range]
A2: =0 -> 0
A3: =1 -> 1
A4: =2 -> 2
A5: =3 -> 3
A6: D
A7: N
A8: [End Format Range]
C9: =_xll.TM1RPTVIEW("region06:Allocation Calculation:2", 0, _xll.TM1RPTTITLE("region06:Allocation List",$C$13), _xll.TM1RPTTITLE("region06:Year",$E$13), _xll.TM1RPTTITLE("region06:Month",$D$13), _xll.TM1RPTTITLE("region06:Version",$F$13),TM1RPTFMTRNG,TM1RPTFMTIDCOL) -> region06:Allocation Calculation:2
C10: Allocation Detail
C12: Allocation List | D12: Month | E12: Year | F12: Version
C13: =_xll.SUBNM("region06:Allocation List","Default","Allocation 1") -> Allocation 1 | D13: =_xll.SUBNM("region06:Month","MQY","Year") -> Year | E13: =_xll.SUBNM("region06:Year","Default","Y2","Caption_Default") -> 2021 | F13: =_xll.SUBNM("region06:Version","Current",_xll.DBR("region06:Calendar","Current Version","String"),"Caption_Default") -> Version1
C15: Description | D15: Source Entity | F15: Source Account | H15: Allocation Driver | J15: Allocation Out
C16: =_xll.DBRW("region06:Allocation Source Definition",$C$13,$E$13,$F$13,"Desc") -> Travel Allocation | D16: =_xll.DBRW("region06:Allocation Source Definition",$C$13,$E$13,$F$13,"zSource") -> Massachusetts | F16: =_xll.DBRW("region06:Allocation Source Definition",$C$13,$E$13,$F$13,$F$15) -> 6199 OFFICE EXPENSE | H16: =_xll.DBRW("region06:Allocation Source Definition",$C$13,$E$13,$F$13,$H$15) -> FTE | J16: =_xll.DBRW("region06:Allocation Source Definition",$C$13,$E$13,$F$13,"Allocation Amount") -> 39600.88
D18: Allocation | E18: Exclude | F18: Driver | G18: Total | H18: Ratio | I18: Allocation | J18: Allocation
D19: Amount | E19: Entity | G19: Driver | I19: In | J19: Out
D20: Allocation Amount | E20: Exclude Entity | F20: Driver | G20: Total Driver | H20: Ratio | I20: Allocation In | J20: Allocation Out
D21: Allocation Amount | E21: Exclude Entity | F21: Driver | G21: Total Driver | H21: Ratio | I21: Allocated Amount | J21: Credit Amount
A22: =IF(_xll.TM1RPTELISCONSOLIDATED($C$22,$C22),IF(_xll.TM1RPTELLEV($C$22,$C22)<=3,_xll.TM1RPTELLEV($C$22,$C22),"D"),"N") -> 0 | C22: =_xll.TM1RPTROW($C$9,"region06:organization","Workflow") -> Total Company | D22: =_xll.DBRW($C$9,$C22,$C$13,$E$13,$D$13,$F$13,D$21) -> 33600.88 | E22: =_xll.DBRW($C$9,$C22,$C$13,$E$13,$D$13,$F$13,E$21) | F22: =_xll.DBRW($C$9,$C22,$C$13,$E$13,$D$13,$F$13,F$21) -> 43 | G22: =_xll.DBRW($C$9,$C22,$C$13,$E$13,$D$13,$F$13,G$21) -> 43 | H22: =_xll.DBRW($C$9,$C22,$C$13,$E$13,$D$13,$F$13,H$21) -> 1 | I22: =_xll.DBRW($C$9,$C22,$C$13,$E$13,$D$13,$F$13,I$21) -> 33600.88 | J22: =_xll.DBRW($C$9,$C22,$C$13,$E$13,$D$13,$F$13,J$21) -> -33600.88
A23: =IF(_xll.TM1RPTELISCONSOLIDATED($C$22,$C23),IF(_xll.TM1RPTELLEV($C$22,$C23)<=3,_xll.TM1RPTELLEV($C$22,$C23),"D"),"N") -> 1 | C23: East Region | D23: =_xll.DBRW($C$9,$C23,$C$13,$E$13,$D$13,$F$13,D$21) -> 33600.88 | E23: =_xll.DBRW($C$9,$C23,$C$13,$E$13,$D$13,$F$13,E$21) | F23: =_xll.DBRW($C$9,$C23,$C$13,$E$13,$D$13,$F$13,F$21) -> 9.5 | G23: =_xll.DBRW($C$9,$C23,$C$13,$E$13,$D$13,$F$13,G$21) -> 43 | H23: =_xll.DBRW($C$9,$C23,$C$13,$E$13,$D$13,$F$13,H$21) -> 0.22093023 | I23: =_xll.DBRW($C$9,$C23,$C$13,$E$13,$D$13,$F$13,I$21) -> 7529.2214 | J23: =_xll.DBRW($C$9,$C23,$C$13,$E$13,$D$13,$F$13,J$21) -> -33600.88
A24: =IF(_xll.TM1RPTELISCONSOLIDATED($C$22,$C24),IF(_xll.TM1RPTELLEV($C$22,$C24)<=3,_xll.TM1RPTELLEV($C$22,$C24),"D"),"N") -> N | C24: Massachusetts | D24: =_xll.DBRW($C$9,$C24,$C$13,$E$13,$D$13,$F$13,D$21) -> 33600.88 | E24: =_xll.DBRW($C$9,$C24,$C$13,$E$13,$D$13,$F$13,E$21) -> Y | F24: =_xll.DBRW($C$9,$C24,$C$13,$E$13,$D$13,$F$13,F$21) -> 0 | G24: =_xll.DBRW($C$9,$C24,$C$13,$E$13,$D$13,$F$13,G$21) -> 43 | H24: =_xll.DBRW($C$9,$C24,$C$13,$E$13,$D$13,$F$13,H$21) -> 0 | I24: =_xll.DBRW($C$9,$C24,$C$13,$E$13,$D$13,$F$13,I$21) -> 0 | J24: =_xll.DBRW($C$9,$C24,$C$13,$E$13,$D$13,$F$13,J$21) -> -33600.88
A25: =IF(_xll.TM1RPTELISCONSOLIDATED($C$22,$C25),IF(_xll.TM1RPTELLEV($C$22,$C25)<=3,_xll.TM1RPTELLEV($C$22,$C25),"D"),"N") -> N | C25: Maryland | D25: =_xll.DBRW($C$9,$C25,$C$13,$E$13,$D$13,$F$13,D$21) -> 33600.88 | E25: =_xll.DBRW($C$9,$C25,$C$13,$E$13,$D$13,$F$13,E$21) | F25: =_xll.DBRW($C$9,$C25,$C$13,$E$13,$D$13,$F$13,F$21) -> 4 | G25: =_xll.DBRW($C$9,$C25,$C$13,$E$13,$D$13,$F$13,G$21) -> 43 | H25: =_xll.DBRW($C$9,$C25,$C$13,$E$13,$D$13,$F$13,H$21) -> 0.093023256 | I25: =_xll.DBRW($C$9,$C25,$C$13,$E$13,$D$13,$F$13,I$21) -> 3170.1985 | J25: =_xll.DBRW($C$9,$C25,$C$13,$E$13,$D$13,$F$13,J$21) -> 0
A26: =IF(_xll.TM1RPTELISCONSOLIDATED($C$22,$C26),IF(_xll.TM1RPTELLEV($C$22,$C26)<=3,_xll.TM1RPTELLEV($C$22,$C26),"D"),"N") -> N | C26: Florida | D26: =_xll.DBRW($C$9,$C26,$C$13,$E$13,$D$13,$F$13,D$21) -> 33600.88 | E26: =_xll.DBRW($C$9,$C26,$C$13,$E$13,$D$13,$F$13,E$21) | F26: =_xll.DBRW($C$9,$C26,$C$13,$E$13,$D$13,$F$13,F$21) -> 5.5 | G26: =_xll.DBRW($C$9,$C26,$C$13,$E$13,$D$13,$F$13,G$21) -> 43 | H26: =_xll.DBRW($C$9,$C26,$C$13,$E$13,$D$13,$F$13,H$21) -> 0.12790698 | I26: =_xll.DBRW($C$9,$C26,$C$13,$E$13,$D$13,$F$13,I$21) -> 4359.0229 | J26: =_xll.DBRW($C$9,$C26,$C$13,$E$13,$D$13,$F$13,J$21) -> 0
A27: =IF(_xll.TM1RPTELISCONSOLIDATED($C$22,$C27),IF(_xll.TM1RPTELLEV($C$22,$C27)<=3,_xll.TM1RPTELLEV($C$22,$C27),"D"),"N") -> 1 | C27: Central Region | D27: =_xll.DBRW($C$9,$C27,$C$13,$E$13,$D$13,$F$13,D$21) -> 33600.88 | E27: =_xll.DBRW($C$9,$C27,$C$13,$E$13,$D$13,$F$13,E$21) | F27: =_xll.DBRW($C$9,$C27,$C$13,$E$13,$D$13,$F$13,F$21) -> 9 | G27: =_xll.DBRW($C$9,$C27,$C$13,$E$13,$D$13,$F$13,G$21) -> 43 | H27: =_xll.DBRW($C$9,$C27,$C$13,$E$13,$D$13,$F$13,H$21) -> 0.20930233 | I27: =_xll.DBRW($C$9,$C27,$C$13,$E$13,$D$13,$F$13,I$21) -> 7132.9466 | J27: =_xll.DBRW($C$9,$C27,$C$13,$E$13,$D$13,$F$13,J$21) -> 0
A28: =IF(_xll.TM1RPTELISCONSOLIDATED($C$22,$C28),IF(_xll.TM1RPTELLEV($C$22,$C28)<=3,_xll.TM1RPTELLEV($C$22,$C28),"D"),"N") -> N | C28: Michigan | D28: =_xll.DBRW($C$9,$C28,$C$13,$E$13,$D$13,$F$13,D$21) -> 33600.88 | E28: =_xll.DBRW($C$9,$C28,$C$13,$E$13,$D$13,$F$13,E$21) | F28: =_xll.DBRW($C$9,$C28,$C$13,$E$13,$D$13,$F$13,F$21) -> 5 | G28: =_xll.DBRW($C$9,$C28,$C$13,$E$13,$D$13,$F$13,G$21) -> 43 | H28: =_xll.DBRW($C$9,$C28,$C$13,$E$13,$D$13,$F$13,H$21) -> 0.11627907 | I28: =_xll.DBRW($C$9,$C28,$C$13,$E$13,$D$13,$F$13,I$21) -> 3962.7481 | J28: =_xll.DBRW($C$9,$C28,$C$13,$E$13,$D$13,$F$13,J$21) -> 0
A29: =IF(_xll.TM1RPTELISCONSOLIDATED($C$22,$C29),IF(_xll.TM1RPTELLEV($C$22,$C29)<=3,_xll.TM1RPTELLEV($C$22,$C29),"D"),"N") -> N | C29: Illinois | D29: =_xll.DBRW($C$9,$C29,$C$13,$E$13,$D$13,$F$13,D$21) -> 33600.88 | E29: =_xll.DBRW($C$9,$C29,$C$13,$E$13,$D$13,$F$13,E$21) | F29: =_xll.DBRW($C$9,$C29,$C$13,$E$13,$D$13,$F$13,F$21) -> 4 | G29: =_xll.DBRW($C$9,$C29,$C$13,$E$13,$D$13,$F$13,G$21) -> 43 | H29: =_xll.DBRW($C$9,$C29,$C$13,$E$13,$D$13,$F$13,H$21) -> 0.093023256 | I29: =_xll.DBRW($C$9,$C29,$C$13,$E$13,$D$13,$F$13,I$21) -> 3170.1985 | J29: =_xll.DBRW($C$9,$C29,$C$13,$E$13,$D$13,$F$13,J$21) -> 0
A30: =IF(_xll.TM1RPTELISCONSOLIDATED($C$22,$C30),IF(_xll.TM1RPTELLEV($C$22,$C30)<=3,_xll.TM1RPTELLEV($C$22,$C30),"D"),"N") -> 1 | C30: West Region | D30: =_xll.DBRW($C$9,$C30,$C$13,$E$13,$D$13,$F$13,D$21) -> 33600.88 | E30: =_xll.DBRW($C$9,$C30,$C$13,$E$13,$D$13,$F$13,E$21) | F30: =_xll.DBRW($C$9,$C30,$C$13,$E$13,$D$13,$F$13,F$21) -> 9.5 | G30: =_xll.DBRW($C$9,$C30,$C$13,$E$13,$D$13,$F$13,G$21) -> 43 | H30: =_xll.DBRW($C$9,$C30,$C$13,$E$13,$D$13,$F$13,H$21) -> 0.22093023 | I30: =_xll.DBRW($C$9,$C30,$C$13,$E$13,$D$13,$F$13,I$21) -> 7050.4678 | J30: =_xll.DBRW($C$9,$C30,$C$13,$E$13,$D$13,$F$13,J$21) -> 0
A31: =IF(_xll.TM1RPTELISCONSOLIDATED($C$22,$C31),IF(_xll.TM1RPTELLEV($C$22,$C31)<=3,_xll.TM1RPTELLEV($C$22,$C31),"D"),"N") -> N | C31: California | D31: =_xll.DBRW($C$9,$C31,$C$13,$E$13,$D$13,$F$13,D$21) -> 33600.88 | E31: =_xll.DBRW($C$9,$C31,$C$13,$E$13,$D$13,$F$13,E$21) | F31: =_xll.DBRW($C$9,$C31,$C$13,$E$13,$D$13,$F$13,F$21) -> 4.5 | G31: =_xll.DBRW($C$9,$C31,$C$13,$E$13,$D$13,$F$13,G$21) -> 43 | H31: =_xll.DBRW($C$9,$C31,$C$13,$E$13,$D$13,$F$13,H$21) -> 0.10465116 | I31: =_xll.DBRW($C$9,$C31,$C$13,$E$13,$D$13,$F$13,I$21) -> 3566.4733 | J31: =_xll.DBRW($C$9,$C31,$C$13,$E$13,$D$13,$F$13,J$21) -> 0
A32: =IF(_xll.TM1RPTELISCONSOLIDATED($C$22,$C32),IF(_xll.TM1RPTELLEV($C$22,$C32)<=3,_xll.TM1RPTELLEV($C$22,$C32),"D"),"N") -> N | C32: Washington | D32: =_xll.DBRW($C$9,$C32,$C$13,$E$13,$D$13,$F$13,D$21) -> 33600.88 | E32: =_xll.DBRW($C$9,$C32,$C$13,$E$13,$D$13,$F$13,E$21) | F32: =_xll.DBRW($C$9,$C32,$C$13,$E$13,$D$13,$F$13,F$21) -> 5 | G32: =_xll.DBRW($C$9,$C32,$C$13,$E$13,$D$13,$F$13,G$21) -> 43 | H32: =_xll.DBRW($C$9,$C32,$C$13,$E$13,$D$13,$F$13,H$21) -> 0.11627907 | I32: =_xll.DBRW($C$9,$C32,$C$13,$E$13,$D$13,$F$13,I$21) -> 3483.9946 | J32: =_xll.DBRW($C$9,$C32,$C$13,$E$13,$D$13,$F$13,J$21) -> 0
A33: =IF(_xll.TM1RPTELISCONSOLIDATED($C$22,$C33),IF(_xll.TM1RPTELLEV($C$22,$C33)<=3,_xll.TM1RPTELLEV($C$22,$C33),"D"),"N") -> 1 | C33: Canada | D33: =_xll.DBRW($C$9,$C33,$C$13,$E$13,$D$13,$F$13,D$21) -> 33600.88 | E33: =_xll.DBRW($C$9,$C33,$C$13,$E$13,$D$13,$F$13,E$21) | F33: =_xll.DBRW($C$9,$C33,$C$13,$E$13,$D$13,$F$13,F$21) -> 15 | G33: =_xll.DBRW($C$9,$C33,$C$13,$E$13,$D$13,$F$13,G$21) -> 43 | H33: =_xll.DBRW($C$9,$C33,$C$13,$E$13,$D$13,$F$13,H$21) -> 0.34883721 | I33: =_xll.DBRW($C$9,$C33,$C$13,$E$13,$D$13,$F$13,I$21) -> 11888.244 | J33: =_xll.DBRW($C$9,$C33,$C$13,$E$13,$D$13,$F$13,J$21) -> 0
A34: =IF(_xll.TM1RPTELISCONSOLIDATED($C$22,$C34),IF(_xll.TM1RPTELLEV($C$22,$C34)<=3,_xll.TM1RPTELLEV($C$22,$C34),"D"),"N") -> N | C34: Ontario | D34: =_xll.DBRW($C$9,$C34,$C$13,$E$13,$D$13,$F$13,D$21) -> 33600.88 | E34: =_xll.DBRW($C$9,$C34,$C$13,$E$13,$D$13,$F$13,E$21) | F34: =_xll.DBRW($C$9,$C34,$C$13,$E$13,$D$13,$F$13,F$21) -> 5 | G34: =_xll.DBRW($C$9,$C34,$C$13,$E$13,$D$13,$F$13,G$21) -> 43 | H34: =_xll.DBRW($C$9,$C34,$C$13,$E$13,$D$13,$F$13,H$21) -> 0.11627907 | I34: =_xll.DBRW($C$9,$C34,$C$13,$E$13,$D$13,$F$13,I$21) -> 3962.7481 | J34: =_xll.DBRW($C$9,$C34,$C$13,$E$13,$D$13,$F$13,J$21) -> 0
... A36: =IF(_xll.TM1RPTELISCONSOLIDATED($C$22,$C36),IF(_xll.TM1RPTELLEV($C$22,$C36)<=3,_xll.TM1RPTELLEV($C$22,$C36),"D"),"N") -> N | C36: British Columbia | D36: =_xll.DBRW($C$9,$C36,$C$13,$E$13,$D$13,$F$13,D$21) -> 33600.88 | E36: =_xll.DBRW($C$9,$C36,$C$13,$E$13,$D$13,$F$13,E$21) | F36: =_xll.DBRW($C$9,$C36,$C$13,$E$13,$D$13,$F$13,F$21) -> 5.5 | G36: =_xll.DBRW($C$9,$C36,$C$13,$E$13,$D$13,$F$13,G$21) -> 43 | H36: =_xll.DBRW($C$9,$C36,$C$13,$E$13,$D$13,$F$13,H$21) -> 0.12790698 | I36: =_xll.DBRW($C$9,$C36,$C$13,$E$13,$D$13,$F$13,I$21) -> 4359.0229 | J36: =_xll.DBRW($C$9,$C36,$C$13,$E$13,$D$13,$F$13,J$21) -> 0

Sheet AllocSummary
B1: CUBE: | C1: =_xll.VIEW("region06:Allocation Calculation",$B$5,"!",$E$5,$D$5,$F$5,"!") -> region06:Allocation Calculation
B2: Allocation Summary
B4: Organization | D4: Month | E4: Year | F4: Version
B5: =_xll.SUBNM("region06:organization","Default","101","Caption_Base") -> Massachusetts | D5: =_xll.SUBNM("region06:Month","Default","Year") -> Year | E5: =_xll.SUBNM("region06:Year","Default","Y2","Caption_Default") -> 2021 | F5: =_xll.SUBNM("region06:Version","Current",_xll.DBR("region06:Calendar","Current Version","String"),"Caption_Default") -> Version1
C7: Source | D7: Source | E7: Allocation | F7: Allocation | G7: Ratio | H7: Credit | I7: Allocation
C8: Entity | D8: Account | E8: Drive | F8: Amount | H8: Amount | I8: Total
C9: Source Entity | D9: Source Account | E9: Allocation Driver | F9: Allocated Amount | G9: Ratio | H9: Credit Amount | I9: Credit Amount
B10: Allocation 1 | C10: =_xll.DBRW($C$1,$B$5,$B10,$E$5,$D$5,$F$5,C$9) -> Massachusetts | D10: =_xll.DBRW($C$1,$B$5,$B10,$E$5,$D$5,$F$5,D$9) -> 6199 OFFICE EXPENSE | E10: =_xll.DBRW($C$1,$B$5,$B10,$E$5,$D$5,$F$5,E$9) -> FTE | F10: =_xll.DBRW($C$1,$B$5,$B10,$E$5,$D$5,$F$5,F$9) -> 0 | G10: =_xll.DBRW($C$1,$B$5,$B10,$E$5,$D$5,$F$5,G$9) -> 0 | H10: =_xll.DBRW($C$1,$B$5,$B10,$E$5,$D$5,$F$5,H$9) -> -33600.88 | I10: =IF(ISERR(F10+H10),0,F10+H10) -> -33600.88
B11: Allocation 2 | C11: =_xll.DBRW($C$1,$B$5,$B11,$E$5,$D$5,$F$5,C$9) -> Maryland | D11: =_xll.DBRW($C$1,$B$5,$B11,$E$5,$D$5,$F$5,D$9) -> 6099 PAYROLL | E11: =_xll.DBRW($C$1,$B$5,$B11,$E$5,$D$5,$F$5,E$9) -> Server Space | F11: =_xll.DBRW($C$1,$B$5,$B11,$E$5,$D$5,$F$5,F$9) -> 10664.335 | G11: =_xll.DBRW($C$1,$B$5,$B11,$E$5,$D$5,$F$5,G$9) -> 0.018867925 | H11: =_xll.DBRW($C$1,$B$5,$B11,$E$5,$D$5,$F$5,H$9) -> 0 | I11: =IF(ISERR(F11+H11),0,F11+H11) -> 10664.335
B12: Allocation 3 | C12: =_xll.DBRW($C$1,$B$5,$B12,$E$5,$D$5,$F$5,C$9) -> Florida | D12: =_xll.DBRW($C$1,$B$5,$B12,$E$5,$D$5,$F$5,D$9) -> 6399 OCCUPANCY | E12: =_xll.DBRW($C$1,$B$5,$B12,$E$5,$D$5,$F$5,E$9) -> Square Footage | F12: =_xll.DBRW($C$1,$B$5,$B12,$E$5,$D$5,$F$5,F$9) -> 6230.7692 | G12: =_xll.DBRW($C$1,$B$5,$B12,$E$5,$D$5,$F$5,G$9) -> 0.019230769 | H12: =_xll.DBRW($C$1,$B$5,$B12,$E$5,$D$5,$F$5,H$9) -> 0 | I12: =IF(ISERR(F12+H12),0,F12+H12) -> 6230.7692
B13: Allocation 4 | C13: =_xll.DBRW($C$1,$B$5,$B13,$E$5,$D$5,$F$5,C$9) -> California | D13: =_xll.DBRW($C$1,$B$5,$B13,$E$5,$D$5,$F$5,D$9) -> Total Operating Expense | E13: =_xll.DBRW($C$1,$B$5,$B13,$E$5,$D$5,$F$5,E$9) -> 4999 Gross Revenue | F13: =_xll.DBRW($C$1,$B$5,$B13,$E$5,$D$5,$F$5,F$9) -> 182737.55 | G13: =_xll.DBRW($C$1,$B$5,$B13,$E$5,$D$5,$F$5,G$9) -> 0.12241213 | H13: =_xll.DBRW($C$1,$B$5,$B13,$E$5,$D$5,$F$5,H$9) -> 0 | I13: =IF(ISERR(F13+H13),0,F13+H13) -> 182737.55
B14: Allocation 5 | C14: =_xll.DBRW($C$1,$B$5,$B14,$E$5,$D$5,$F$5,C$9) -> Florida | D14: =_xll.DBRW($C$1,$B$5,$B14,$E$5,$D$5,$F$5,D$9) -> Total Operating Expense | E14: =_xll.DBRW($C$1,$B$5,$B14,$E$5,$D$5,$F$5,E$9) -> Net Profit | F14: =_xll.DBRW($C$1,$B$5,$B14,$E$5,$D$5,$F$5,F$9) -> 74229.654 | G14: =_xll.DBRW($C$1,$B$5,$B14,$E$5,$D$5,$F$5,G$9) -> 0.047419301 | H14: =_xll.DBRW($C$1,$B$5,$B14,$E$5,$D$5,$F$5,H$9) -> 0 | I14: =IF(ISERR(F14+H14),0,F14+H14) -> 74229.654
B15: Allocation 6 | C15: =_xll.DBRW($C$1,$B$5,$B15,$E$5,$D$5,$F$5,C$9) -> Ontario | D15: =_xll.DBRW($C$1,$B$5,$B15,$E$5,$D$5,$F$5,D$9) -> 6120 Office Supplies | E15: =_xll.DBRW($C$1,$B$5,$B15,$E$5,$D$5,$F$5,E$9) -> FTE | F15: =_xll.DBRW($C$1,$B$5,$B15,$E$5,$D$5,$F$5,F$9) -> 447.77304 | G15: =_xll.DBRW($C$1,$B$5,$B15,$E$5,$D$5,$F$5,G$9) -> 0.10588235 | H15: =_xll.DBRW($C$1,$B$5,$B15,$E$5,$D$5,$F$5,H$9) -> 0 | I15: =IF(ISERR(F15+H15),0,F15+H15) -> 447.77304
B16: Allocation 7 | C16: =_xll.DBRW($C$1,$B$5,$B16,$E$5,$D$5,$F$5,C$9) -> Quebec | D16: =_xll.DBRW($C$1,$B$5,$B16,$E$5,$D$5,$F$5,D$9) -> 6000 Salaries | E16: =_xll.DBRW($C$1,$B$5,$B16,$E$5,$D$5,$F$5,E$9) -> Net Profit | F16: =_xll.DBRW($C$1,$B$5,$B16,$E$5,$D$5,$F$5,F$9) -> 13737.273 | G16: =_xll.DBRW($C$1,$B$5,$B16,$E$5,$D$5,$F$5,G$9) -> 0.060428391 | H16: =_xll.DBRW($C$1,$B$5,$B16,$E$5,$D$5,$F$5,H$9) -> 0 | I16: =IF(ISERR(F16+H16),0,F16+H16) -> 13737.273
B17: Allocation 8 | C17: =_xll.DBRW($C$1,$B$5,$B17,$E$5,$D$5,$F$5,C$9) -> British Columbia | D17: =_xll.DBRW($C$1,$B$5,$B17,$E$5,$D$5,$F$5,D$9) -> 6099 PAYROLL | E17: =_xll.DBRW($C$1,$B$5,$B17,$E$5,$D$5,$F$5,E$9) -> Square Footage | F17: =_xll.DBRW($C$1,$B$5,$B17,$E$5,$D$5,$F$5,F$9) -> 2250.7907 | G17: =_xll.DBRW($C$1,$B$5,$B17,$E$5,$D$5,$F$5,G$9) -> 0.022222222 | H17: =_xll.DBRW($C$1,$B$5,$B17,$E$5,$D$5,$F$5,H$9) -> 0 | I17: =IF(ISERR(F17+H17),0,F17+H17) -> 2250.7907
B18: Allocation 9 | C18: =_xll.DBRW($C$1,$B$5,$B18,$E$5,$D$5,$F$5,C$9) -> Massachusetts | D18: =_xll.DBRW($C$1,$B$5,$B18,$E$5,$D$5,$F$5,D$9) -> 6100 Insurance | E18: =_xll.DBRW($C$1,$B$5,$B18,$E$5,$D$5,$F$5,E$9) -> FTE | F18: =_xll.DBRW($C$1,$B$5,$B18,$E$5,$D$5,$F$5,F$9) -> 0 | G18: =_xll.DBRW($C$1,$B$5,$B18,$E$5,$D$5,$F$5,G$9) -> 0 | H18: =_xll.DBRW($C$1,$B$5,$B18,$E$5,$D$5,$F$5,H$9) -> -8389 | I18: =IF(ISERR(F18+H18),0,F18+H18) -> -8389
B19: Allocation 10 | C19: =_xll.DBRW($C$1,$B$5,$B19,$E$5,$D$5,$F$5,C$9) -> Florida | D19: =_xll.DBRW($C$1,$B$5,$B19,$E$5,$D$5,$F$5,D$9) -> 6310 Utilities | E19: =_xll.DBRW($C$1,$B$5,$B19,$E$5,$D$5,$F$5,E$9) -> Square Footage | F19: =_xll.DBRW($C$1,$B$5,$B19,$E$5,$D$5,$F$5,F$9) -> 1800 | G19: =_xll.DBRW($C$1,$B$5,$B19,$E$5,$D$5,$F$5,G$9) -> 0.019230769 | H19: =_xll.DBRW($C$1,$B$5,$B19,$E$5,$D$5,$F$5,H$9) -> 0 | I19: =IF(ISERR(F19+H19),0,F19+H19) -> 1800
B20: All Allocations | F20: =_xll.DBRW($C$1,$B$5,$B20,$E$5,$D$5,$F$5,F$9) -> 292098.14 | H20: =_xll.DBRW($C$1,$B$5,$B20,$E$5,$D$5,$F$5,H$9) -> -41989.88 | I20: =IF(ISERR(F20+H20),0,F20+H20) -> 250108.26

Sheet PLReport
B1: CUBE: | C1: =_xll.VIEW("region06:Income Statement",$D$5,$B$5,$G$5,$E$5,"!","!") -> region06:Income Statement
B2: Summary P&L | C2: Allocation Detail
B4: Organization | D4: Currency | E4: Month | G4: Year
B5: =_xll.SUBNM("region06:organization","Workflow","101","Caption_Default") -> Massachusetts | D5: =_xll.SUBNM("region06:Currency Calc","Default","Local") -> Local | E5: =_xll.SUBNM("region06:Month","MY","Year") -> Year | G5: =_xll.SUBNM("region06:Year","Default","Y2","Caption_Default") -> 2021
D7: PY Actuals | E7: Target | F7: =F8 -> Version1 | G7: Var | H7: Var %
D8: Prior Year Actual | E8: Target | F8: =_xll.SUBNM("region06:Version","Current",_xll.DBR("region06:Calendar","Current Version","String"),"Caption_Default") -> Version1 | G8: Variance | H8: Variance%
B9: Gross Margin
B10: Gross Revenue | C10: 4999 Gross Revenue | D10: =_xll.DBRW($C$1,$D$5,$B$5,$G$5,$E$5,$C10,D$8) -> 10495091 | E10: =_xll.DBRW($C$1,$D$5,$B$5,$G$5,$E$5,$C10,E$8) -> 12817315 | F10: =_xll.DBRW($C$1,$D$5,$B$5,$G$5,$E$5,$C10,F$8) -> 27654743 | G10: =_xll.DBRW($C$1,$D$5,$B$5,$G$5,$E$5,$C10,G$8) -> -20569721 | H10: =_xll.DBRW($C$1,$D$5,$B$5,$G$5,$E$5,$C10,H$8) -> -74.380446
B11: Cost of Sales | C11: 5999 Cost of Sales | D11: =_xll.DBRW($C$1,$D$5,$B$5,$G$5,$E$5,$C11,D$8) -> 8661808.5 | E11: =_xll.DBRW($C$1,$D$5,$B$5,$G$5,$E$5,$C11,E$8) -> 8811382.7 | F11: =_xll.DBRW($C$1,$D$5,$B$5,$G$5,$E$5,$C11,F$8) -> 20932844 | G11: =_xll.DBRW($C$1,$D$5,$B$5,$G$5,$E$5,$C11,G$8) -> 15012087 | H11: =_xll.DBRW($C$1,$D$5,$B$5,$G$5,$E$5,$C11,H$8) -> 71.715469
B12: Gross Margin | C12: Gross Margin | D12: =_xll.DBRW($C$1,$D$5,$B$5,$G$5,$E$5,$C12,D$8) -> 1833282.1 | E12: =_xll.DBRW($C$1,$D$5,$B$5,$G$5,$E$5,$C12,E$8) -> 4005932.4 | F12: =_xll.DBRW($C$1,$D$5,$B$5,$G$5,$E$5,$C12,F$8) -> 6721898.8 | G12: =_xll.DBRW($C$1,$D$5,$B$5,$G$5,$E$5,$C12,G$8) -> -5557633.6 | H12: =_xll.DBRW($C$1,$D$5,$B$5,$G$5,$E$5,$C12,H$8) -> -82.67952
B13: Operating Expense
B14: Payroll | C14: 6099 PAYROLL | D14: =_xll.DBRW($C$1,$D$5,$B$5,$G$5,$E$5,$C14,D$8) -> 710411.92 | E14: =_xll.DBRW($C$1,$D$5,$B$5,$G$5,$E$5,$C14,E$8) -> 710411.92 | F14: =_xll.DBRW($C$1,$D$5,$B$5,$G$5,$E$5,$C14,F$8) -> 688412.59 | G14: =_xll.DBRW($C$1,$D$5,$B$5,$G$5,$E$5,$C14,G$8) -> 7694.3622 | H14: =_xll.DBRW($C$1,$D$5,$B$5,$G$5,$E$5,$C14,H$8) -> 1.1176963
B15: Office Expense | C15: 6199 OFFICE EXPENSE | D15: =_xll.DBRW($C$1,$D$5,$B$5,$G$5,$E$5,$C15,D$8) -> 67120.543 | E15: =_xll.DBRW($C$1,$D$5,$B$5,$G$5,$E$5,$C15,E$8) -> 67120.543 | F15: =_xll.DBRW($C$1,$D$5,$B$5,$G$5,$E$5,$C15,F$8) -> 79201.76 | G15: =_xll.DBRW($C$1,$D$5,$B$5,$G$5,$E$5,$C15,G$8) -> 13297.76 | H15: =_xll.DBRW($C$1,$D$5,$B$5,$G$5,$E$5,$C15,H$8) -> 16.789728
B16: Travel | C16: 6299 TRAVEL | D16: =_xll.DBRW($C$1,$D$5,$B$5,$G$5,$E$5,$C16,D$8) -> 45415.518 | E16: =_xll.DBRW($C$1,$D$5,$B$5,$G$5,$E$5,$C16,E$8) -> 45415.518 | F16: =_xll.DBRW($C$1,$D$5,$B$5,$G$5,$E$5,$C16,F$8) -> 45228 | G16: =_xll.DBRW($C$1,$D$5,$B$5,$G$5,$E$5,$C16,G$8) -> 2280 | H16: =_xll.DBRW($C$1,$D$5,$B$5,$G$5,$E$5,$C16,H$8) -> 5.041125
B17: Occupancy | C17: 6399 OCCUPANCY | D17: =_xll.DBRW($C$1,$D$5,$B$5,$G$5,$E$5,$C17,D$8) -> 536653.7 | E17: =_xll.DBRW($C$1,$D$5,$B$5,$G$5,$E$5,$C17,E$8) -> 536653.7 | F17: =_xll.DBRW($C$1,$D$5,$B$5,$G$5,$E$5,$C17,F$8) -> 330000 | G17: =_xll.DBRW($C$1,$D$5,$B$5,$G$5,$E$5,$C17,G$8) -> -175797 | H17: =_xll.DBRW($C$1,$D$5,$B$5,$G$5,$E$5,$C17,H$8) -> -53.271818
B18: Marketing | C18: 6499 MARKETING | D18: =_xll.DBRW($C$1,$D$5,$B$5,$G$5,$E$5,$C18,D$8) -> 99851.304 | E18: =_xll.DBRW($C$1,$D$5,$B$5,$G$5,$E$5,$C18,E$8) -> 99851.304 | F18: =_xll.DBRW($C$1,$D$5,$B$5,$G$5,$E$5,$C18,F$8) -> 681310.8 | G18: =_xll.DBRW($C$1,$D$5,$B$5,$G$5,$E$5,$C18,G$8) -> 581086.8 | H18: =_xll.DBRW($C$1,$D$5,$B$5,$G$5,$E$5,$C18,H$8) -> 85.289533
B19: Depreciation | C19: 6599 DEPRECIATION | D19: =_xll.DBRW($C$1,$D$5,$B$5,$G$5,$E$5,$C19,D$8) -> 134270.06 | E19: =_xll.DBRW($C$1,$D$5,$B$5,$G$5,$E$5,$C19,E$8) -> 134270.06 | F19: =_xll.DBRW($C$1,$D$5,$B$5,$G$5,$E$5,$C19,F$8) -> 170583.33 | G19: =_xll.DBRW($C$1,$D$5,$B$5,$G$5,$E$5,$C19,G$8) -> 26583.333 | H19: =_xll.DBRW($C$1,$D$5,$B$5,$G$5,$E$5,$C19,H$8) -> 15.583781
B20: Total Operating Expense | C20: Total Operating Expense | D20: =_xll.DBRW($C$1,$D$5,$B$5,$G$5,$E$5,$C20,D$8) -> 1593723 | E20: =_xll.DBRW($C$1,$D$5,$B$5,$G$5,$E$5,$C20,E$8) -> 1593723 | F20: =_xll.DBRW($C$1,$D$5,$B$5,$G$5,$E$5,$C20,F$8) -> 1994736.5 | G20: =_xll.DBRW($C$1,$D$5,$B$5,$G$5,$E$5,$C20,G$8) -> 455145.26 | H20: =_xll.DBRW($C$1,$D$5,$B$5,$G$5,$E$5,$C20,H$8) -> 22.817312
B22: Net Profit | C22: Net Profit | D22: =_xll.DBRW($C$1,$D$5,$B$5,$G$5,$E$5,$C22,D$8) -> 239559.04 | E22: =_xll.DBRW($C$1,$D$5,$B$5,$G$5,$E$5,$C22,E$8) -> 2412209.3 | F22: =_xll.DBRW($C$1,$D$5,$B$5,$G$5,$E$5,$C22,F$8) -> 4727162.3 | G22: =_xll.DBRW($C$1,$D$5,$B$5,$G$5,$E$5,$C22,G$8) -> -5102488.4 | H22: =_xll.DBRW($C$1,$D$5,$B$5,$G$5,$E$5,$C22,H$8) -> -107.93978
B24: Allocations | C24: 6699 ALLOCATIONS | D24: =_xll.DBRW($C$1,$D$5,$B$5,$G$5,$E$5,$C24,D$8) -> 11965.313 | E24: =_xll.DBRW($C$1,$D$5,$B$5,$G$5,$E$5,$C24,E$8) -> 11965.313 | F24: =_xll.DBRW($C$1,$D$5,$B$5,$G$5,$E$5,$C24,F$8) -> 250108.26 | G24: =_xll.DBRW($C$1,$D$5,$B$5,$G$5,$E$5,$C24,G$8) -> 218379.38 | H24: =_xll.DBRW($C$1,$D$5,$B$5,$G$5,$E$5,$C24,H$8) -> 87.313939
B26: Net Profit After Allocations | C26: Net Profit After Allocations | D26: =_xll.DBRW($C$1,$D$5,$B$5,$G$5,$E$5,$C26,D$8) -> 227593.73 | E26: =_xll.DBRW($C$1,$D$5,$B$5,$G$5,$E$5,$C26,E$8) -> 2400244 | F26: =_xll.DBRW($C$1,$D$5,$B$5,$G$5,$E$5,$C26,F$8) -> 4477054 | G26: =_xll.DBRW($C$1,$D$5,$B$5,$G$5,$E$5,$C26,G$8) -> -4884109 | H26: =_xll.DBRW($C$1,$D$5,$B$5,$G$5,$E$5,$C26,H$8) -> -109.09203

Sheet Fcst
A1: [Begin Format Range]
A2: 0
A3: 1
A4: 2
A5: 3
A6: D
A7: N
A8: 0_Jan
A9: 1_Jan
A10: 2_Jan
A11: 3_Jan
A12: D_Jan
... A79: N_Dec
A80: [End Format Range] | H80: =VLOOKUP($I$85,Lookup!$D$2:$E$3,2,0) -> 0 | I80: =IF(#REF!<>"","{TM1FILTERBYPATTERN( {TM1SUBSETALL( [Account] )}, """&#REF!&""")}","") -> #REF!
C81: =_xll.TM1RPTVIEW("region06:Income Statement:3", $H$80, _xll.TM1RPTTITLE("region06:Currency Calc",$D$85), _xll.TM1RPTTITLE("region06:organization",$C$85), _xll.TM1RPTTITLE("region06:Year",$E$85), _xll.TM1RPTTITLE("region06:Version",$F$85),TM1RPTFMTRNG,TM1RPTFMTIDCOL) -> region06:Income Statement:3
C82: Forecast P&L
C84: Organization | D84: Currency | E84: Year | F84: Version | H84: Fcst Period | I84: Supress Zero
C85: =_xll.SUBNM("region06:organization","Workflow","Total Company","Caption_Default") -> Total Company | D85: =_xll.SUBNM("region06:Currency Calc","Default","Local") -> Local | E85: =_xll.SUBNM("region06:Year","Default","Y2","Caption_Default") -> 2021 | F85: Forecast | H85: =_xll.DBRW("region06:calendar","Fcst Month","String") -> Jul | I85: No
D87: Act/Fcst: | E87: =E88 -> A | F87: =F88 -> A | G87: =G88 -> A | H87: =H88 -> A | I87: =I88 -> A | J87: =J88 -> A | K87: =K88 -> F | L87: =L88 -> F | ... P87: =P88 -> F
D88: Act/Fcst: | E88: =_xll.DBRW("region06:Relative Time",$E$85,E$89,"ActFor") -> A | F88: =_xll.DBRW("region06:Relative Time",$E$85,F$89,"ActFor") -> A | G88: =_xll.DBRW("region06:Relative Time",$E$85,G$89,"ActFor") -> A | H88: =_xll.DBRW("region06:Relative Time",$E$85,H$89,"ActFor") -> A | I88: =_xll.DBRW("region06:Relative Time",$E$85,I$89,"ActFor") -> A | J88: =_xll.DBRW("region06:Relative Time",$E$85,J$89,"ActFor") -> A | K88: =_xll.DBRW("region06:Relative Time",$E$85,K$89,"ActFor") -> F | L88: =_xll.DBRW("region06:Relative Time",$E$85,L$89,"ActFor") -> F | ... P88: =_xll.DBRW("region06:Relative Time",$E$85,P$89,"ActFor") -> F
D89: Fcst Method | E89: Jan | F89: Feb | G89: Mar | H89: Apr | I89: May | J89: Jun | K89: Jul | L89: Aug | M89: Sep | N89: Oct | O89: Nov | P89: Dec | Q89: Year
A91: =IF(_xll.TM1RPTELISCONSOLIDATED($C$91,$C91),IF(_xll.TM1RPTELLEV($C$91,$C91)<=3,_xll.TM1RPTELLEV($C$91,$C91),"D"),"N") -> N | C91: =_xll.TM1RPTROW($C$81,"region06:Account","Summary",,"Caption_Default",1) -> 4999 Gross Revenue | D91: =_xll.DBRW("region06:FcstMethod",$C91,"FcstMethod") -> Remaining Budget | E91: =_xll.DBRW($C$81,$D$85,$C$85,$E$85,E$89,$C91,$F$85) -> 5122390.7 | F91: =_xll.DBRW($C$81,$D$85,$C$85,$E$85,F$89,$C91,$F$85) -> 6154509.6 | G91: =_xll.DBRW($C$81,$D$85,$C$85,$E$85,G$89,$C91,$F$85) -> 8014283.8 | H91: =_xll.DBRW($C$81,$D$85,$C$85,$E$85,H$89,$C91,$F$85) -> 7398190.7 | I91: =_xll.DBRW($C$81,$D$85,$C$85,$E$85,I$89,$C91,$F$85) -> 7172213.8 | J91: =_xll.DBRW($C$81,$D$85,$C$85,$E$85,J$89,$C91,$F$85) -> 6013042.8 | K91: =_xll.DBRW($C$81,$D$85,$C$85,$E$85,K$89,$C91,$F$85) -> 52992623 | L91: =_xll.DBRW($C$81,$D$85,$C$85,$E$85,L$89,$C91,$F$85) -> 48348821 | ... Q91: =_xll.DBRW($C$81,$D$85,$C$85,$E$85,Q$89,$C91,$F$85) -> 2.3951948e+08
A92: =IF(_xll.TM1RPTELISCONSOLIDATED($C$91,$C92),IF(_xll.TM1RPTELLEV($C$91,$C92)<=3,_xll.TM1RPTELLEV($C$91,$C92),"D"),"N") -> N | C92: 5999 Cost of Sales | D92: =_xll.DBRW("region06:FcstMethod",$C92,"FcstMethod") -> Last Year Actual | E92: =_xll.DBRW($C$81,$D$85,$C$85,$E$85,E$89,$C92,$F$85) -> 3144045.8 | F92: =_xll.DBRW($C$81,$D$85,$C$85,$E$85,F$89,$C92,$F$85) -> 3725157.9 | G92: =_xll.DBRW($C$81,$D$85,$C$85,$E$85,G$89,$C92,$F$85) -> 4744819.5 | H92: =_xll.DBRW($C$81,$D$85,$C$85,$E$85,H$89,$C92,$F$85) -> 4416873.4 | I92: =_xll.DBRW($C$81,$D$85,$C$85,$E$85,I$89,$C92,$F$85) -> 4329861.7 | J92: =_xll.DBRW($C$81,$D$85,$C$85,$E$85,J$89,$C92,$F$85) -> 3691393.9 | K92: =_xll.DBRW($C$81,$D$85,$C$85,$E$85,K$89,$C92,$F$85) -> 5206614.9 | L92: =_xll.DBRW($C$81,$D$85,$C$85,$E$85,L$89,$C92,$F$85) -> 4898537.5 | ... Q92: =_xll.DBRW($C$81,$D$85,$C$85,$E$85,Q$89,$C92,$F$85) -> 49919182
A93: =IF(_xll.TM1RPTELISCONSOLIDATED($C$91,$C93),IF(_xll.TM1RPTELLEV($C$91,$C93)<=3,_xll.TM1RPTELLEV($C$91,$C93),"D"),"N") -> 2 | C93: Gross Margin | D93: =_xll.DBRW("region06:FcstMethod",$C93,"FcstMethod") -> Last Year Actual | E93: =_xll.DBRW($C$81,$D$85,$C$85,$E$85,E$89,$C93,$F$85) -> 1978344.9 | F93: =_xll.DBRW($C$81,$D$85,$C$85,$E$85,F$89,$C93,$F$85) -> 2429351.7 | G93: =_xll.DBRW($C$81,$D$85,$C$85,$E$85,G$89,$C93,$F$85) -> 3269464.3 | H93: =_xll.DBRW($C$81,$D$85,$C$85,$E$85,H$89,$C93,$F$85) -> 2981317.2 | I93: =_xll.DBRW($C$81,$D$85,$C$85,$E$85,I$89,$C93,$F$85) -> 2842352.1 | J93: =_xll.DBRW($C$81,$D$85,$C$85,$E$85,J$89,$C93,$F$85) -> 2321649 | K93: =_xll.DBRW($C$81,$D$85,$C$85,$E$85,K$89,$C93,$F$85) -> 47786008 | L93: =_xll.DBRW($C$81,$D$85,$C$85,$E$85,L$89,$C93,$F$85) -> 43450283 | ... Q93: =_xll.DBRW($C$81,$D$85,$C$85,$E$85,Q$89,$C93,$F$85) -> 1.896003e+08
A94: =IF(_xll.TM1RPTELISCONSOLIDATED($C$91,$C94),IF(_xll.TM1RPTELLEV($C$91,$C94)<=3,_xll.TM1RPTELLEV($C$91,$C94),"D"),"N") -> 3 | C94: 6099 PAYROLL | D94: =_xll.DBRW("region06:FcstMethod",$C94,"FcstMethod") -> Budget | E94: =_xll.DBRW($C$81,$D$85,$C$85,$E$85,E$89,$C94,$F$85) -> 558049.83 | F94: =_xll.DBRW($C$81,$D$85,$C$85,$E$85,F$89,$C94,$F$85) -> 570592.12 | G94: =_xll.DBRW($C$81,$D$85,$C$85,$E$85,G$89,$C94,$F$85) -> 580817.52 | H94: =_xll.DBRW($C$81,$D$85,$C$85,$E$85,H$89,$C94,$F$85) -> 584918.18 | I94: =_xll.DBRW($C$81,$D$85,$C$85,$E$85,I$89,$C94,$F$85) -> 587632.67 | J94: =_xll.DBRW($C$81,$D$85,$C$85,$E$85,J$89,$C94,$F$85) -> 591641.87 | K94: =_xll.DBRW($C$81,$D$85,$C$85,$E$85,K$89,$C94,$F$85) -> 565704.65 | L94: =_xll.DBRW($C$81,$D$85,$C$85,$E$85,L$89,$C94,$F$85) -> 565905.24 | ... Q94: =_xll.DBRW($C$81,$D$85,$C$85,$E$85,Q$89,$C94,$F$85) -> 6861839.7
A95: =IF(_xll.TM1RPTELISCONSOLIDATED($C$91,$C95),IF(_xll.TM1RPTELLEV($C$91,$C95)<=3,_xll.TM1RPTELLEV($C$91,$C95),"D"),"N") -> 3 | C95: 6199 OFFICE EXPENSE | D95: =_xll.DBRW("region06:FcstMethod",$C95,"FcstMethod") | E95: =_xll.DBRW($C$81,$D$85,$C$85,$E$85,E$89,$C95,$F$85) -> 54920 | F95: =_xll.DBRW($C$81,$D$85,$C$85,$E$85,F$89,$C95,$F$85) -> 54920 | G95: =_xll.DBRW($C$81,$D$85,$C$85,$E$85,G$89,$C95,$F$85) -> 54920 | H95: =_xll.DBRW($C$81,$D$85,$C$85,$E$85,H$89,$C95,$F$85) -> 54920 | I95: =_xll.DBRW($C$81,$D$85,$C$85,$E$85,I$89,$C95,$F$85) -> 54920 | J95: =_xll.DBRW($C$81,$D$85,$C$85,$E$85,J$89,$C95,$F$85) -> 54920 | K95: =_xll.DBRW($C$81,$D$85,$C$85,$E$85,K$89,$C95,$F$85) -> 54523.684 | L95: =_xll.DBRW($C$81,$D$85,$C$85,$E$85,L$89,$C95,$F$85) -> 54523.684 | ... Q95: =_xll.DBRW($C$81,$D$85,$C$85,$E$85,Q$89,$C95,$F$85) -> 656662.1
A96: =IF(_xll.TM1RPTELISCONSOLIDATED($C$91,$C96),IF(_xll.TM1RPTELLEV($C$91,$C96)<=3,_xll.TM1RPTELLEV($C$91,$C96),"D"),"N") -> 3 | C96: 6299 TRAVEL | D96: =_xll.DBRW("region06:FcstMethod",$C96,"FcstMethod") | E96: =_xll.DBRW($C$81,$D$85,$C$85,$E$85,E$89,$C96,$F$85) -> 35790 | F96: =_xll.DBRW($C$81,$D$85,$C$85,$E$85,F$89,$C96,$F$85) -> 35790 | G96: =_xll.DBRW($C$81,$D$85,$C$85,$E$85,G$89,$C96,$F$85) -> 35790 | H96: =_xll.DBRW($C$81,$D$85,$C$85,$E$85,H$89,$C96,$F$85) -> 35790 | I96: =_xll.DBRW($C$81,$D$85,$C$85,$E$85,I$89,$C96,$F$85) -> 35790 | J96: =_xll.DBRW($C$81,$D$85,$C$85,$E$85,J$89,$C96,$F$85) -> 35790 | K96: =_xll.DBRW($C$81,$D$85,$C$85,$E$85,K$89,$C96,$F$85) -> 39080.224 | L96: =_xll.DBRW($C$81,$D$85,$C$85,$E$85,L$89,$C96,$F$85) -> 39080.224 | ... Q96: =_xll.DBRW($C$81,$D$85,$C$85,$E$85,Q$89,$C96,$F$85) -> 449221.34
A97: =IF(_xll.TM1RPTELISCONSOLIDATED($C$91,$C97),IF(_xll.TM1RPTELLEV($C$91,$C97)<=3,_xll.TM1RPTELLEV($C$91,$C97),"D"),"N") -> 3 | C97: 6399 OCCUPANCY | D97: =_xll.DBRW("region06:FcstMethod",$C97,"FcstMethod") | E97: =_xll.DBRW($C$81,$D$85,$C$85,$E$85,E$89,$C97,$F$85) -> 283550.95 | F97: =_xll.DBRW($C$81,$D$85,$C$85,$E$85,F$89,$C97,$F$85) -> 233807.36 | G97: =_xll.DBRW($C$81,$D$85,$C$85,$E$85,G$89,$C97,$F$85) -> 184063.77 | H97: =_xll.DBRW($C$81,$D$85,$C$85,$E$85,H$89,$C97,$F$85) -> 134320.51 | I97: =_xll.DBRW($C$81,$D$85,$C$85,$E$85,I$89,$C97,$F$85) -> 134320.51 | J97: =_xll.DBRW($C$81,$D$85,$C$85,$E$85,J$89,$C97,$F$85) -> 134320.51 | K97: =_xll.DBRW($C$81,$D$85,$C$85,$E$85,K$89,$C97,$F$85) -> 192780.22 | L97: =_xll.DBRW($C$81,$D$85,$C$85,$E$85,L$89,$C97,$F$85) -> 192780.22 | ... Q97: =_xll.DBRW($C$81,$D$85,$C$85,$E$85,Q$89,$C97,$F$85) -> 2753713.3
A98: =IF(_xll.TM1RPTELISCONSOLIDATED($C$91,$C98),IF(_xll.TM1RPTELLEV($C$91,$C98)<=3,_xll.TM1RPTELLEV($C$91,$C98),"D"),"N") -> 3 | C98: 6499 MARKETING | D98: =_xll.DBRW("region06:FcstMethod",$C98,"FcstMethod") -> Budget | E98: =_xll.DBRW($C$81,$D$85,$C$85,$E$85,E$89,$C98,$F$85) -> 83520 | F98: =_xll.DBRW($C$81,$D$85,$C$85,$E$85,F$89,$C98,$F$85) -> 83520 | G98: =_xll.DBRW($C$81,$D$85,$C$85,$E$85,G$89,$C98,$F$85) -> 83520 | H98: =_xll.DBRW($C$81,$D$85,$C$85,$E$85,H$89,$C98,$F$85) -> 83520 | I98: =_xll.DBRW($C$81,$D$85,$C$85,$E$85,I$89,$C98,$F$85) -> 83520 | J98: =_xll.DBRW($C$81,$D$85,$C$85,$E$85,J$89,$C98,$F$85) -> 83520 | K98: =_xll.DBRW($C$81,$D$85,$C$85,$E$85,K$89,$C98,$F$85) -> 82879.839 | L98: =_xll.DBRW($C$81,$D$85,$C$85,$E$85,L$89,$C98,$F$85) -> 82879.839 | ... Q98: =_xll.DBRW($C$81,$D$85,$C$85,$E$85,Q$89,$C98,$F$85) -> 1002246.8
A99: =IF(_xll.TM1RPTELISCONSOLIDATED($C$91,$C99),IF(_xll.TM1RPTELLEV($C$91,$C99)<=3,_xll.TM1RPTELLEV($C$91,$C99),"D"),"N") -> 3 | C99: 6599 DEPRECIATION | D99: =_xll.DBRW("region06:FcstMethod",$C99,"FcstMethod") | E99: =_xll.DBRW($C$81,$D$85,$C$85,$E$85,E$89,$C99,$F$85) -> 20400 | F99: =_xll.DBRW($C$81,$D$85,$C$85,$E$85,F$89,$C99,$F$85) -> 40087.5 | G99: =_xll.DBRW($C$81,$D$85,$C$85,$E$85,G$89,$C99,$F$85) -> 110212.5 | H99: =_xll.DBRW($C$81,$D$85,$C$85,$E$85,H$89,$C99,$F$85) -> 146962.5 | I99: =_xll.DBRW($C$81,$D$85,$C$85,$E$85,I$89,$C99,$F$85) -> 161962.5 | J99: =_xll.DBRW($C$81,$D$85,$C$85,$E$85,J$89,$C99,$F$85) -> 201150 | K99: =_xll.DBRW($C$81,$D$85,$C$85,$E$85,K$89,$C99,$F$85) -> 170025 | L99: =_xll.DBRW($C$81,$D$85,$C$85,$E$85,L$89,$C99,$F$85) -> 177712.5 | ... Q99: =_xll.DBRW($C$81,$D$85,$C$85,$E$85,Q$89,$C99,$F$85) -> 1747251.4
A100: =IF(_xll.TM1RPTELISCONSOLIDATED($C$91,$C100),IF(_xll.TM1RPTELLEV($C$91,$C100)<=3,_xll.TM1RPTELLEV($C$91,$C100),"D"),"N") -> 2 | C100: Total Operating Expense | D100: =_xll.DBRW("region06:FcstMethod",$C100,"FcstMethod") | E100: =_xll.DBRW($C$81,$D$85,$C$85,$E$85,E$89,$C100,$F$85) -> 1036230.8 | F100: =_xll.DBRW($C$81,$D$85,$C$85,$E$85,F$89,$C100,$F$85) -> 1018717 | G100: =_xll.DBRW($C$81,$D$85,$C$85,$E$85,G$89,$C100,$F$85) -> 1049323.8 | H100: =_xll.DBRW($C$81,$D$85,$C$85,$E$85,H$89,$C100,$F$85) -> 1040431.2 | I100: =_xll.DBRW($C$81,$D$85,$C$85,$E$85,I$89,$C100,$F$85) -> 1058145.7 | J100: =_xll.DBRW($C$81,$D$85,$C$85,$E$85,J$89,$C100,$F$85) -> 1101342.4 | K100: =_xll.DBRW($C$81,$D$85,$C$85,$E$85,K$89,$C100,$F$85) -> 1104993.6 | L100: =_xll.DBRW($C$81,$D$85,$C$85,$E$85,L$89,$C100,$F$85) -> 1112881.7 | ... Q100: =_xll.DBRW($C$81,$D$85,$C$85,$E$85,Q$89,$C100,$F$85) -> 13470935
A101: =IF(_xll.TM1RPTELISCONSOLIDATED($C$91,$C101),IF(_xll.TM1RPTELLEV($C$91,$C101)<=3,_xll.TM1RPTELLEV($C$91,$C101),"D"),"N") -> 1 | C101: Net Profit | D101: =_xll.DBRW("region06:FcstMethod",$C101,"FcstMethod") | E101: =_xll.DBRW($C$81,$D$85,$C$85,$E$85,E$89,$C101,$F$85) -> 942114.13 | F101: =_xll.DBRW($C$81,$D$85,$C$85,$E$85,F$89,$C101,$F$85) -> 1410634.8 | G101: =_xll.DBRW($C$81,$D$85,$C$85,$E$85,G$89,$C101,$F$85) -> 2220140.5 | H101: =_xll.DBRW($C$81,$D$85,$C$85,$E$85,H$89,$C101,$F$85) -> 1940886.1 | I101: =_xll.DBRW($C$81,$D$85,$C$85,$E$85,I$89,$C101,$F$85) -> 1784206.4 | J101: =_xll.DBRW($C$81,$D$85,$C$85,$E$85,J$89,$C101,$F$85) -> 1220306.6 | K101: =_xll.DBRW($C$81,$D$85,$C$85,$E$85,K$89,$C101,$F$85) -> 46681014 | L101: =_xll.DBRW($C$81,$D$85,$C$85,$E$85,L$89,$C101,$F$85) -> 42337402 | ... Q101: =_xll.DBRW($C$81,$D$85,$C$85,$E$85,Q$89,$C101,$F$85) -> 1.7612936e+08
A102: =IF(_xll.TM1RPTELISCONSOLIDATED($C$91,$C102),IF(_xll.TM1RPTELLEV($C$91,$C102)<=3,_xll.TM1RPTELLEV($C$91,$C102),"D"),"N") -> 1 | C102: 6699 ALLOCATIONS | D102: =_xll.DBRW("region06:FcstMethod",$C102,"FcstMethod") | E102: =_xll.DBRW($C$81,$D$85,$C$85,$E$85,E$89,$C102,$F$85) -> 0 | F102: =_xll.DBRW($C$81,$D$85,$C$85,$E$85,F$89,$C102,$F$85) -> 0 | G102: =_xll.DBRW($C$81,$D$85,$C$85,$E$85,G$89,$C102,$F$85) -> 7.2759576e-12 | H102: =_xll.DBRW($C$81,$D$85,$C$85,$E$85,H$89,$C102,$F$85) -> 7.2759576e-12 | I102: =_xll.DBRW($C$81,$D$85,$C$85,$E$85,I$89,$C102,$F$85) -> -7.2759576e-12 | J102: =_xll.DBRW($C$81,$D$85,$C$85,$E$85,J$89,$C102,$F$85) -> -7.2759576e-12 | K102: =_xll.DBRW($C$81,$D$85,$C$85,$E$85,K$89,$C102,$F$85) -> 0 | L102: =_xll.DBRW($C$81,$D$85,$C$85,$E$85,L$89,$C102,$F$85) -> 5.8207661e-11 | ... Q102: =_xll.DBRW($C$81,$D$85,$C$85,$E$85,Q$89,$C102,$F$85) -> 5.8207661e-11
A103: =IF(_xll.TM1RPTELISCONSOLIDATED($C$91,$C103),IF(_xll.TM1RPTELLEV($C$91,$C103)<=3,_xll.TM1RPTELLEV($C$91,$C103),"D"),"N") -> 0 | C103: Net Profit After Allocations | D103: =_xll.DBRW("region06:FcstMethod",$C103,"FcstMethod") | E103: =_xll.DBRW($C$81,$D$85,$C$85,$E$85,E$89,$C103,$F$85) -> 942114.13 | F103: =_xll.DBRW($C$81,$D$85,$C$85,$E$85,F$89,$C103,$F$85) -> 1410634.8 | G103: =_xll.DBRW($C$81,$D$85,$C$85,$E$85,G$89,$C103,$F$85) -> 2220140.5 | H103: =_xll.DBRW($C$81,$D$85,$C$85,$E$85,H$89,$C103,$F$85) -> 1940886.1 | I103: =_xll.DBRW($C$81,$D$85,$C$85,$E$85,I$89,$C103,$F$85) -> 1784206.4 | J103: =_xll.DBRW($C$81,$D$85,$C$85,$E$85,J$89,$C103,$F$85) -> 1220306.6 | K103: =_xll.DBRW($C$81,$D$85,$C$85,$E$85,K$89,$C103,$F$85) -> 46681014 | L103: =_xll.DBRW($C$81,$D$85,$C$85,$E$85,L$89,$C103,$F$85) -> 42337402 | ... Q103: =_xll.DBRW($C$81,$D$85,$C$85,$E$85,Q$89,$C103,$F$85) -> 1.7612936e+08

Sheet FcstDetail
D1: CUBE: | E1: =_xll.VIEW("region06:Income Statement",$K$5,$D$5,$M$5,"!",$F$5,"!") -> region06:Income Statement
D2: Forecast P&L Details ($000)
D4: Organization | F4: Account | I4: Fcst Method | K4: Currency | M4: Year | O4: Fcst Period
D5: =_xll.SUBNM("region06:organization","Workflow","101","Caption_Default") -> Massachusetts | F5: =_xll.SUBNM("region06:Account","","4999","Caption_Default") -> 4999 Gross Revenue | I5: =_xll.DBRW("region06:FcstMethod",$F5,"FcstMethod") -> Remaining Budget | K5: =_xll.SUBNM("region06:Currency Calc","Default","Local") -> Local | M5: =_xll.SUBNM("region06:Year","Default","Y2","Caption_Default") -> 2021 | O5: =_xll.DBRW("region06:calendar","Fcst Month","String") -> Jul
E7: =E8 -> A | F7: =F8 -> A | G7: =G8 -> A | H7: =H8 -> A | I7: =I8 -> A | J7: =J8 -> A | K7: =K8 -> F | L7: =L8 -> F | ... P7: =P8 -> F
E8: =_xll.DBRW("region06:Relative Time",$M$5,E$9,"ActFor") -> A | F8: =_xll.DBRW("region06:Relative Time",$M$5,F$9,"ActFor") -> A | G8: =_xll.DBRW("region06:Relative Time",$M$5,G$9,"ActFor") -> A | H8: =_xll.DBRW("region06:Relative Time",$M$5,H$9,"ActFor") -> A | I8: =_xll.DBRW("region06:Relative Time",$M$5,I$9,"ActFor") -> A | J8: =_xll.DBRW("region06:Relative Time",$M$5,J$9,"ActFor") -> A | K8: =_xll.DBRW("region06:Relative Time",$M$5,K$9,"ActFor") -> F | L8: =_xll.DBRW("region06:Relative Time",$M$5,L$9,"ActFor") -> F | ... P8: =_xll.DBRW("region06:Relative Time",$M$5,P$9,"ActFor") -> F
D9: ($000) | E9: Jan | F9: Feb | G9: Mar | H9: Apr | I9: May | J9: Jun | K9: Jul | L9: Aug | M9: Sep | N9: Oct | O9: Nov | P9: Dec | Q9: Year
B11: Prior Year Actual | C11: Actual | D11: Actual | E11: =_xll.DBRW($E$1,$K$5,$D$5,$M$5,E$9,$F$5,$C11) -> 458462.22 | F11: =_xll.DBRW($E$1,$K$5,$D$5,$M$5,F$9,$F$5,$C11) -> 547920.06 | G11: =_xll.DBRW($E$1,$K$5,$D$5,$M$5,G$9,$F$5,$C11) -> 702486.13 | H11: =_xll.DBRW($E$1,$K$5,$D$5,$M$5,H$9,$F$5,$C11) -> 653076.79 | I11: =_xll.DBRW($E$1,$K$5,$D$5,$M$5,I$9,$F$5,$C11) -> 633421.38 | J11: =_xll.DBRW($E$1,$K$5,$D$5,$M$5,J$9,$F$5,$C11) -> 539394.99 | K11: =_xll.DBRW($E$1,$K$5,$D$5,$M$5,K$9,$F$5,$C11) -> 534003.88 | L11: =_xll.DBRW($E$1,$K$5,$D$5,$M$5,L$9,$F$5,$C11) -> 501258.51 | ... Q11: =_xll.DBRW($E$1,$K$5,$D$5,$M$5,Q$9,$F$5,$C11) -> 7085021.8
B12: =_xll.SUBNM("region06:Version","Current",_xll.DBR("region06:Calendar","Current Version","String"),"Caption_Default") -> Version1 | C12: Budget | D12: =_xll.SUBNM("region06:Version","Current",_xll.DBR("region06:Calendar","Current Version","String"),"Caption_Default") -> Version1 | E12: =_xll.DBRW($E$1,$K$5,$D$5,$M$5,E$9,$F$5,$B12) -> 1519216.5 | F12: =_xll.DBRW($E$1,$K$5,$D$5,$M$5,F$9,$F$5,$B12) -> 9714163.3 | G12: =_xll.DBRW($E$1,$K$5,$D$5,$M$5,G$9,$F$5,$B12) -> 976291.84 | H12: =_xll.DBRW($E$1,$K$5,$D$5,$M$5,H$9,$F$5,$B12) -> 894887.04 | I12: =_xll.DBRW($E$1,$K$5,$D$5,$M$5,I$9,$F$5,$B12) -> 802150.83 | J12: =_xll.DBRW($E$1,$K$5,$D$5,$M$5,J$9,$F$5,$B12) -> 1040327.2 | K12: =_xll.DBRW($E$1,$K$5,$D$5,$M$5,K$9,$F$5,$B12) -> 3505016.7 | L12: =_xll.DBRW($E$1,$K$5,$D$5,$M$5,L$9,$F$5,$B12) -> 3206024.5 | ... Q12: =_xll.DBRW($E$1,$K$5,$D$5,$M$5,Q$9,$F$5,$B12) -> 27654743
